package micdoodle8.mods.galacticraft.core.wgen;

import java.util.Random;

import micdoodle8.mods.galacticraft.core.blocks.GCCoreBlocks;
import micdoodle8.mods.galacticraft.core.tile.GCCoreTileEntityLandingPad;
import net.minecraft.world.World;
import net.minecraft.world.gen.feature.WorldGenerator;

public class GCCoreWorldGenSpaceStation extends WorldGenerator
{
	public boolean generate(World world, Random rand, int i, int j, int k) 
	{
		world.setBlockAndMetadataWithNotify(i + 0, j + 0, k + 0, GCCoreBlocks.decorationBlocks.blockID, 4, 3);
		world.setBlockAndMetadataWithNotify(i + 0, j + 0, k + 1, GCCoreBlocks.decorationBlocks.blockID, 4, 3);
		world.setBlockAndMetadataWithNotify(i + 0, j + 0, k + 2, GCCoreBlocks.decorationBlocks.blockID, 4, 3);
		world.setBlockAndMetadataWithNotify(i + 0, j + 0, k + 3, GCCoreBlocks.decorationBlocks.blockID, 4, 3);
		world.setBlockAndMetadataWithNotify(i + 0, j + 0, k + 4, GCCoreBlocks.decorationBlocks.blockID, 4, 3);
		world.setBlockAndMetadataWithNotify(i + 0, j + 0, k + 5, GCCoreBlocks.decorationBlocks.blockID, 4, 3);
		world.setBlockAndMetadataWithNotify(i + 0, j + 0, k + 6, GCCoreBlocks.decorationBlocks.blockID, 4, 3);
		world.setBlockAndMetadataWithNotify(i + 0, j + 1, k + 0, GCCoreBlocks.decorationBlocks.blockID, 4, 3);
		world.setBlockAndMetadataWithNotify(i + 0, j + 1, k + 1, GCCoreBlocks.decorationBlocks.blockID, 4, 3);
		world.setBlockAndMetadataWithNotify(i + 0, j + 1, k + 2, GCCoreBlocks.decorationBlocks.blockID, 4, 3);
		world.setBlockAndMetadataWithNotify(i + 0, j + 1, k + 3, GCCoreBlocks.decorationBlocks.blockID, 4, 3);
		world.setBlockAndMetadataWithNotify(i + 0, j + 1, k + 4, GCCoreBlocks.decorationBlocks.blockID, 4, 3);
		world.setBlockAndMetadataWithNotify(i + 0, j + 1, k + 5, GCCoreBlocks.decorationBlocks.blockID, 4, 3);
		world.setBlockAndMetadataWithNotify(i + 0, j + 1, k + 6, GCCoreBlocks.decorationBlocks.blockID, 4, 3);
		world.setBlockAndMetadataWithNotify(i + 1, j + 0, k + 0, GCCoreBlocks.decorationBlocks.blockID, 4, 3);
		world.setBlockAndMetadataWithNotify(i + 1, j + 0, k + 1, GCCoreBlocks.decorationBlocks.blockID, 4, 3);
		world.setBlockAndMetadataWithNotify(i + 1, j + 0, k + 2, GCCoreBlocks.decorationBlocks.blockID, 4, 3);
		world.setBlockAndMetadataWithNotify(i + 1, j + 0, k + 3, GCCoreBlocks.decorationBlocks.blockID, 4, 3);
		world.setBlockAndMetadataWithNotify(i + 1, j + 0, k + 4, GCCoreBlocks.decorationBlocks.blockID, 4, 3);
		world.setBlockAndMetadataWithNotify(i + 1, j + 0, k + 5, GCCoreBlocks.decorationBlocks.blockID, 4, 3);
		world.setBlockAndMetadataWithNotify(i + 1, j + 0, k + 6, GCCoreBlocks.decorationBlocks.blockID, 4, 3);
		world.setBlockAndMetadataWithNotify(i + 1, j + 1, k + 0, GCCoreBlocks.decorationBlocks.blockID, 4, 3);
		world.setBlockAndMetadataWithNotify(i + 1, j + 1, k + 6, GCCoreBlocks.decorationBlocks.blockID, 4, 3);
		world.setBlockAndMetadataWithNotify(i + 2, j + 0, k + 0, GCCoreBlocks.decorationBlocks.blockID, 4, 3);
		world.setBlockAndMetadataWithNotify(i + 2, j + 0, k + 1, GCCoreBlocks.decorationBlocks.blockID, 4, 3);
		world.setBlockAndMetadataWithNotify(i + 2, j + 0, k + 2, GCCoreBlocks.decorationBlocks.blockID, 4, 3);
		world.setBlockAndMetadataWithNotify(i + 2, j + 0, k + 3, GCCoreBlocks.decorationBlocks.blockID, 4, 3);
		world.setBlockAndMetadataWithNotify(i + 2, j + 0, k + 4, GCCoreBlocks.decorationBlocks.blockID, 4, 3);
		world.setBlockAndMetadataWithNotify(i + 2, j + 0, k + 5, GCCoreBlocks.decorationBlocks.blockID, 4, 3);
		world.setBlockAndMetadataWithNotify(i + 2, j + 0, k + 6, GCCoreBlocks.decorationBlocks.blockID, 4, 3);
		world.setBlockAndMetadataWithNotify(i + 2, j + 1, k + 0, GCCoreBlocks.decorationBlocks.blockID, 4, 3);
		world.setBlockAndMetadataWithNotify(i + 2, j + 1, k + 6, GCCoreBlocks.decorationBlocks.blockID, 4, 3);
		world.setBlockAndMetadataWithNotify(i + 3, j + 0, k + 0, GCCoreBlocks.decorationBlocks.blockID, 4, 3);
		world.setBlockAndMetadataWithNotify(i + 3, j + 0, k + 1, GCCoreBlocks.decorationBlocks.blockID, 4, 3);
		world.setBlockAndMetadataWithNotify(i + 3, j + 0, k + 2, GCCoreBlocks.decorationBlocks.blockID, 4, 3);
		world.setBlockAndMetadataWithNotify(i + 3, j + 0, k + 3, GCCoreBlocks.decorationBlocks.blockID, 4, 3);
		world.setBlockAndMetadataWithNotify(i + 3, j + 0, k + 4, GCCoreBlocks.decorationBlocks.blockID, 4, 3);
		world.setBlockAndMetadataWithNotify(i + 3, j + 0, k + 5, GCCoreBlocks.decorationBlocks.blockID, 4, 3);
		world.setBlockAndMetadataWithNotify(i + 3, j + 0, k + 6, GCCoreBlocks.decorationBlocks.blockID, 4, 3);
		world.setBlockAndMetadataWithNotify(i + 3, j + 1, k + 0, GCCoreBlocks.decorationBlocks.blockID, 4, 3);
		
		
		
		world.setBlockAndMetadataWithNotify(i + 3, j + 1, k + 3, GCCoreBlocks.landingPadFull.blockID, 0, 3);
		world.setBlockTileEntity(i + 3, j + 1, k + 3, new GCCoreTileEntityLandingPad());
		
		
		world.setBlockAndMetadataWithNotify(i + 3, j + 1, k + 6, GCCoreBlocks.decorationBlocks.blockID, 4, 3);
		world.setBlockAndMetadataWithNotify(i + 4, j + 0, k + 0, GCCoreBlocks.decorationBlocks.blockID, 4, 3);
		world.setBlockAndMetadataWithNotify(i + 4, j + 0, k + 1, GCCoreBlocks.decorationBlocks.blockID, 4, 3);
		world.setBlockAndMetadataWithNotify(i + 4, j + 0, k + 2, GCCoreBlocks.decorationBlocks.blockID, 4, 3);
		world.setBlockAndMetadataWithNotify(i + 4, j + 0, k + 3, GCCoreBlocks.decorationBlocks.blockID, 4, 3);
		world.setBlockAndMetadataWithNotify(i + 4, j + 0, k + 4, GCCoreBlocks.decorationBlocks.blockID, 4, 3);
		world.setBlockAndMetadataWithNotify(i + 4, j + 0, k + 5, GCCoreBlocks.decorationBlocks.blockID, 4, 3);
		world.setBlockAndMetadataWithNotify(i + 4, j + 0, k + 6, GCCoreBlocks.decorationBlocks.blockID, 4, 3);
		world.setBlockAndMetadataWithNotify(i + 4, j + 1, k + 0, GCCoreBlocks.decorationBlocks.blockID, 4, 3);
		world.setBlockAndMetadataWithNotify(i + 4, j + 1, k + 6, GCCoreBlocks.decorationBlocks.blockID, 4, 3);
		world.setBlockAndMetadataWithNotify(i + 5, j + 0, k + 0, GCCoreBlocks.decorationBlocks.blockID, 4, 3);
		world.setBlockAndMetadataWithNotify(i + 5, j + 0, k + 1, GCCoreBlocks.decorationBlocks.blockID, 4, 3);
		world.setBlockAndMetadataWithNotify(i + 5, j + 0, k + 2, GCCoreBlocks.decorationBlocks.blockID, 4, 3);
		world.setBlockAndMetadataWithNotify(i + 5, j + 0, k + 3, GCCoreBlocks.decorationBlocks.blockID, 4, 3);
		world.setBlockAndMetadataWithNotify(i + 5, j + 0, k + 4, GCCoreBlocks.decorationBlocks.blockID, 4, 3);
		world.setBlockAndMetadataWithNotify(i + 5, j + 0, k + 5, GCCoreBlocks.decorationBlocks.blockID, 4, 3);
		world.setBlockAndMetadataWithNotify(i + 5, j + 0, k + 6, GCCoreBlocks.decorationBlocks.blockID, 4, 3);
		world.setBlockAndMetadataWithNotify(i + 5, j + 1, k + 0, GCCoreBlocks.decorationBlocks.blockID, 4, 3);
		world.setBlockAndMetadataWithNotify(i + 5, j + 1, k + 6, GCCoreBlocks.decorationBlocks.blockID, 4, 3);
		world.setBlockAndMetadataWithNotify(i + 6, j + 1, k + 0, GCCoreBlocks.decorationBlocks.blockID, 4, 3);
		world.setBlockAndMetadataWithNotify(i + 6, j + 1, k + 1, GCCoreBlocks.decorationBlocks.blockID, 4, 3);
		world.setBlockAndMetadataWithNotify(i + 6, j + 1, k + 2, GCCoreBlocks.decorationBlocks.blockID, 4, 3);
		world.setBlockAndMetadataWithNotify(i + 6, j + 1, k + 3, GCCoreBlocks.decorationBlocks.blockID, 4, 3);
		world.setBlockAndMetadataWithNotify(i + 6, j + 1, k + 4, GCCoreBlocks.decorationBlocks.blockID, 4, 3);
		world.setBlockAndMetadataWithNotify(i + 6, j + 1, k + 5, GCCoreBlocks.decorationBlocks.blockID, 4, 3);
		world.setBlockAndMetadataWithNotify(i + 6, j + 1, k + 6, GCCoreBlocks.decorationBlocks.blockID, 4, 3);
		world.setBlockAndMetadataWithNotify(i + 6, j + 2, k + 0, GCCoreBlocks.decorationBlocks.blockID, 4, 3);
		world.setBlockAndMetadataWithNotify(i + 6, j + 2, k + 6, GCCoreBlocks.decorationBlocks.blockID, 4, 3);
		world.setBlockAndMetadataWithNotify(i + 6, j + 3, k + 0, GCCoreBlocks.decorationBlocks.blockID, 4, 3);
		world.setBlockAndMetadataWithNotify(i + 6, j + 3, k + 6, GCCoreBlocks.decorationBlocks.blockID, 4, 3);
		world.setBlockAndMetadataWithNotify(i + 6, j + 4, k + 0, GCCoreBlocks.decorationBlocks.blockID, 4, 3);
		world.setBlockAndMetadataWithNotify(i + 6, j + 4, k + 6, GCCoreBlocks.decorationBlocks.blockID, 4, 3);
		world.setBlockAndMetadataWithNotify(i + 6, j + 5, k + 0, GCCoreBlocks.decorationBlocks.blockID, 4, 3);
		world.setBlockAndMetadataWithNotify(i + 6, j + 5, k + 1, GCCoreBlocks.decorationBlocks.blockID, 4, 3);
		world.setBlockAndMetadataWithNotify(i + 6, j + 5, k + 2, GCCoreBlocks.decorationBlocks.blockID, 4, 3);
		world.setBlockAndMetadataWithNotify(i + 6, j + 5, k + 3, GCCoreBlocks.decorationBlocks.blockID, 4, 3);
		world.setBlockAndMetadataWithNotify(i + 6, j + 5, k + 4, GCCoreBlocks.decorationBlocks.blockID, 4, 3);
		world.setBlockAndMetadataWithNotify(i + 6, j + 5, k + 5, GCCoreBlocks.decorationBlocks.blockID, 4, 3);
		world.setBlockAndMetadataWithNotify(i + 6, j + 5, k + 6, GCCoreBlocks.decorationBlocks.blockID, 4, 3);
		world.setBlockAndMetadataWithNotify(i + 7, j + 1, k + 0, GCCoreBlocks.decorationBlocks.blockID, 4, 3);
		world.setBlockAndMetadataWithNotify(i + 7, j + 1, k + 1, GCCoreBlocks.decorationBlocks.blockID, 4, 3);
		world.setBlockAndMetadataWithNotify(i + 7, j + 1, k + 2, GCCoreBlocks.decorationBlocks.blockID, 4, 3);
		world.setBlockAndMetadataWithNotify(i + 7, j + 1, k + 3, GCCoreBlocks.decorationBlocks.blockID, 4, 3);
		world.setBlockAndMetadataWithNotify(i + 7, j + 1, k + 4, GCCoreBlocks.decorationBlocks.blockID, 4, 3);
		world.setBlockAndMetadataWithNotify(i + 7, j + 1, k + 5, GCCoreBlocks.decorationBlocks.blockID, 4, 3);
		world.setBlockAndMetadataWithNotify(i + 7, j + 1, k + 6, GCCoreBlocks.decorationBlocks.blockID, 4, 3);
		world.setBlockAndMetadataWithNotify(i + 7, j + 2, k + 0, GCCoreBlocks.decorationBlocks.blockID, 4, 3);
		world.setBlockAndMetadataWithNotify(i + 7, j + 2, k + 1, GCCoreBlocks.decorationBlocks.blockID, 4, 3);
		world.setBlockAndMetadataWithNotify(i + 7, j + 2, k + 5, GCCoreBlocks.decorationBlocks.blockID, 4, 3);
		world.setBlockAndMetadataWithNotify(i + 7, j + 2, k + 6, GCCoreBlocks.decorationBlocks.blockID, 4, 3);
		world.setBlockAndMetadataWithNotify(i + 7, j + 3, k + 0, GCCoreBlocks.decorationBlocks.blockID, 4, 3);
		world.setBlockAndMetadataWithNotify(i + 7, j + 3, k + 1, GCCoreBlocks.decorationBlocks.blockID, 4, 3);
		world.setBlockAndMetadataWithNotify(i + 7, j + 3, k + 5, GCCoreBlocks.decorationBlocks.blockID, 4, 3);
		world.setBlockAndMetadataWithNotify(i + 7, j + 3, k + 6, GCCoreBlocks.decorationBlocks.blockID, 4, 3);
		world.setBlockAndMetadataWithNotify(i + 7, j + 4, k + 0, GCCoreBlocks.decorationBlocks.blockID, 4, 3);
		world.setBlockAndMetadataWithNotify(i + 7, j + 4, k + 1, GCCoreBlocks.decorationBlocks.blockID, 4, 3);
		world.setBlockAndMetadataWithNotify(i + 7, j + 4, k + 5, GCCoreBlocks.decorationBlocks.blockID, 4, 3);
		world.setBlockAndMetadataWithNotify(i + 7, j + 4, k + 6, GCCoreBlocks.decorationBlocks.blockID, 4, 3);
		world.setBlockAndMetadataWithNotify(i + 7, j + 5, k + 0, GCCoreBlocks.decorationBlocks.blockID, 4, 3);
		world.setBlockAndMetadataWithNotify(i + 7, j + 5, k + 1, GCCoreBlocks.decorationBlocks.blockID, 4, 3);
		world.setBlockAndMetadataWithNotify(i + 7, j + 5, k + 2, GCCoreBlocks.decorationBlocks.blockID, 4, 3);
		world.setBlockAndMetadataWithNotify(i + 7, j + 5, k + 3, GCCoreBlocks.decorationBlocks.blockID, 4, 3);
		world.setBlockAndMetadataWithNotify(i + 7, j + 5, k + 4, GCCoreBlocks.decorationBlocks.blockID, 4, 3);
		world.setBlockAndMetadataWithNotify(i + 7, j + 5, k + 5, GCCoreBlocks.decorationBlocks.blockID, 4, 3);
		world.setBlockAndMetadataWithNotify(i + 7, j + 5, k + 6, GCCoreBlocks.decorationBlocks.blockID, 4, 3);
		world.setBlockAndMetadataWithNotify(i + 7, j + 6, k + 0, GCCoreBlocks.decorationBlocks.blockID, 4, 3);
		world.setBlockAndMetadataWithNotify(i + 7, j + 6, k + 1, GCCoreBlocks.decorationBlocks.blockID, 4, 3);
		world.setBlockAndMetadataWithNotify(i + 7, j + 6, k + 2, GCCoreBlocks.decorationBlocks.blockID, 4, 3);
		world.setBlockAndMetadataWithNotify(i + 7, j + 6, k + 3, GCCoreBlocks.decorationBlocks.blockID, 4, 3);
		world.setBlockAndMetadataWithNotify(i + 7, j + 6, k + 4, GCCoreBlocks.decorationBlocks.blockID, 4, 3);
		world.setBlockAndMetadataWithNotify(i + 7, j + 6, k + 5, GCCoreBlocks.decorationBlocks.blockID, 4, 3);
		world.setBlockAndMetadataWithNotify(i + 7, j + 6, k + 6, GCCoreBlocks.decorationBlocks.blockID, 4, 3);
		world.setBlockAndMetadataWithNotify(i + 8, j + 1, k + 0, GCCoreBlocks.decorationBlocks.blockID, 4, 3);
		world.setBlockAndMetadataWithNotify(i + 8, j + 1, k + 1, GCCoreBlocks.decorationBlocks.blockID, 4, 3);
		world.setBlockAndMetadataWithNotify(i + 8, j + 1, k + 2, GCCoreBlocks.decorationBlocks.blockID, 4, 3);
		world.setBlockAndMetadataWithNotify(i + 8, j + 1, k + 3, GCCoreBlocks.decorationBlocks.blockID, 4, 3);
		world.setBlockAndMetadataWithNotify(i + 8, j + 1, k + 4, GCCoreBlocks.decorationBlocks.blockID, 4, 3);
		world.setBlockAndMetadataWithNotify(i + 8, j + 1, k + 5, GCCoreBlocks.decorationBlocks.blockID, 4, 3);
		world.setBlockAndMetadataWithNotify(i + 8, j + 1, k + 6, GCCoreBlocks.decorationBlocks.blockID, 4, 3);
		world.setBlockAndMetadataWithNotify(i + 8, j + 2, k + 0, GCCoreBlocks.decorationBlocks.blockID, 4, 3);
		world.setBlockAndMetadataWithNotify(i + 8, j + 2, k + 6, GCCoreBlocks.decorationBlocks.blockID, 4, 3);
		world.setBlockAndMetadataWithNotify(i + 8, j + 3, k + 0, 102, 0, 3);
		world.setBlockAndMetadataWithNotify(i + 8, j + 3, k + 6, 102, 0, 3);
		world.setBlockAndMetadataWithNotify(i + 8, j + 4, k + 0, GCCoreBlocks.decorationBlocks.blockID, 4, 3);
		world.setBlockAndMetadataWithNotify(i + 8, j + 4, k + 6, GCCoreBlocks.decorationBlocks.blockID, 4, 3);
		world.setBlockAndMetadataWithNotify(i + 8, j + 5, k + 0, GCCoreBlocks.decorationBlocks.blockID, 4, 3);
		world.setBlockAndMetadataWithNotify(i + 8, j + 5, k + 6, GCCoreBlocks.decorationBlocks.blockID, 4, 3);
		world.setBlockAndMetadataWithNotify(i + 8, j + 6, k + 0, GCCoreBlocks.decorationBlocks.blockID, 4, 3);
		world.setBlockAndMetadataWithNotify(i + 8, j + 6, k + 1, GCCoreBlocks.decorationBlocks.blockID, 4, 3);
		world.setBlockAndMetadataWithNotify(i + 8, j + 6, k + 2, GCCoreBlocks.decorationBlocks.blockID, 4, 3);
		world.setBlockAndMetadataWithNotify(i + 8, j + 6, k + 3, GCCoreBlocks.decorationBlocks.blockID, 4, 3);
		world.setBlockAndMetadataWithNotify(i + 8, j + 6, k + 4, GCCoreBlocks.decorationBlocks.blockID, 4, 3);
		world.setBlockAndMetadataWithNotify(i + 8, j + 6, k + 5, GCCoreBlocks.decorationBlocks.blockID, 4, 3);
		world.setBlockAndMetadataWithNotify(i + 8, j + 6, k + 6, GCCoreBlocks.decorationBlocks.blockID, 4, 3);
		world.setBlockAndMetadataWithNotify(i + 9, j + 1, k + 0, GCCoreBlocks.decorationBlocks.blockID, 4, 3);
		world.setBlockAndMetadataWithNotify(i + 9, j + 1, k + 1, GCCoreBlocks.decorationBlocks.blockID, 4, 3);
		world.setBlockAndMetadataWithNotify(i + 9, j + 1, k + 2, GCCoreBlocks.decorationBlocks.blockID, 4, 3);
		world.setBlockAndMetadataWithNotify(i + 9, j + 1, k + 3, GCCoreBlocks.decorationBlocks.blockID, 4, 3);
		world.setBlockAndMetadataWithNotify(i + 9, j + 1, k + 4, GCCoreBlocks.decorationBlocks.blockID, 4, 3);
		world.setBlockAndMetadataWithNotify(i + 9, j + 1, k + 5, GCCoreBlocks.decorationBlocks.blockID, 4, 3);
		world.setBlockAndMetadataWithNotify(i + 9, j + 1, k + 6, GCCoreBlocks.decorationBlocks.blockID, 4, 3);
		world.setBlockAndMetadataWithNotify(i + 9, j + 5, k + 0, GCCoreBlocks.decorationBlocks.blockID, 4, 3);
		world.setBlockAndMetadataWithNotify(i + 9, j + 5, k + 6, GCCoreBlocks.decorationBlocks.blockID, 4, 3);
		world.setBlockAndMetadataWithNotify(i + 9, j + 6, k + 0, GCCoreBlocks.decorationBlocks.blockID, 4, 3);
		world.setBlockAndMetadataWithNotify(i + 9, j + 6, k + 1, GCCoreBlocks.decorationBlocks.blockID, 4, 3);
		world.setBlockAndMetadataWithNotify(i + 9, j + 6, k + 2, GCCoreBlocks.decorationBlocks.blockID, 4, 3);
		world.setBlockAndMetadataWithNotify(i + 9, j + 6, k + 3, GCCoreBlocks.decorationBlocks.blockID, 4, 3);
		world.setBlockAndMetadataWithNotify(i + 9, j + 6, k + 4, GCCoreBlocks.decorationBlocks.blockID, 4, 3);
		world.setBlockAndMetadataWithNotify(i + 9, j + 6, k + 5, GCCoreBlocks.decorationBlocks.blockID, 4, 3);
		world.setBlockAndMetadataWithNotify(i + 9, j + 6, k + 6, GCCoreBlocks.decorationBlocks.blockID, 4, 3);
		world.setBlockAndMetadataWithNotify(i + 10, j + 1, k + 0, GCCoreBlocks.decorationBlocks.blockID, 4, 3);
		world.setBlockAndMetadataWithNotify(i + 10, j + 1, k + 1, GCCoreBlocks.decorationBlocks.blockID, 4, 3);
		world.setBlockAndMetadataWithNotify(i + 10, j + 1, k + 2, GCCoreBlocks.decorationBlocks.blockID, 4, 3);
		world.setBlockAndMetadataWithNotify(i + 10, j + 1, k + 3, GCCoreBlocks.decorationBlocks.blockID, 4, 3);
		world.setBlockAndMetadataWithNotify(i + 10, j + 1, k + 4, GCCoreBlocks.decorationBlocks.blockID, 4, 3);
		world.setBlockAndMetadataWithNotify(i + 10, j + 1, k + 5, GCCoreBlocks.decorationBlocks.blockID, 4, 3);
		world.setBlockAndMetadataWithNotify(i + 10, j + 1, k + 6, GCCoreBlocks.decorationBlocks.blockID, 4, 3);
		
		
//		world.setBlockAndMetadataWithNotify(i + 10, j + 2, k + 3, 3, 0, 3);
		
		
		world.setBlockAndMetadataWithNotify(i + 10, j + 5, k + 0, GCCoreBlocks.decorationBlocks.blockID, 4, 3);
		world.setBlockAndMetadataWithNotify(i + 10, j + 5, k + 6, GCCoreBlocks.decorationBlocks.blockID, 4, 3);
		world.setBlockAndMetadataWithNotify(i + 10, j + 6, k + 0, GCCoreBlocks.decorationBlocks.blockID, 4, 3);
		world.setBlockAndMetadataWithNotify(i + 10, j + 6, k + 1, GCCoreBlocks.decorationBlocks.blockID, 4, 3);
		world.setBlockAndMetadataWithNotify(i + 10, j + 6, k + 2, GCCoreBlocks.decorationBlocks.blockID, 4, 3);
		world.setBlockAndMetadataWithNotify(i + 10, j + 6, k + 3, GCCoreBlocks.decorationBlocks.blockID, 4, 3);
		world.setBlockAndMetadataWithNotify(i + 10, j + 6, k + 4, GCCoreBlocks.decorationBlocks.blockID, 4, 3);
		world.setBlockAndMetadataWithNotify(i + 10, j + 6, k + 5, GCCoreBlocks.decorationBlocks.blockID, 4, 3);
		world.setBlockAndMetadataWithNotify(i + 10, j + 6, k + 6, GCCoreBlocks.decorationBlocks.blockID, 4, 3);
		world.setBlockAndMetadataWithNotify(i + 11, j + 1, k + 0, GCCoreBlocks.decorationBlocks.blockID, 4, 3);
		world.setBlockAndMetadataWithNotify(i + 11, j + 1, k + 1, GCCoreBlocks.decorationBlocks.blockID, 4, 3);
		world.setBlockAndMetadataWithNotify(i + 11, j + 1, k + 2, GCCoreBlocks.decorationBlocks.blockID, 4, 3);
		world.setBlockAndMetadataWithNotify(i + 11, j + 1, k + 3, GCCoreBlocks.decorationBlocks.blockID, 4, 3);
		world.setBlockAndMetadataWithNotify(i + 11, j + 1, k + 4, GCCoreBlocks.decorationBlocks.blockID, 4, 3);
		world.setBlockAndMetadataWithNotify(i + 11, j + 1, k + 5, GCCoreBlocks.decorationBlocks.blockID, 4, 3);
		world.setBlockAndMetadataWithNotify(i + 11, j + 1, k + 6, GCCoreBlocks.decorationBlocks.blockID, 4, 3);
		world.setBlockAndMetadataWithNotify(i + 11, j + 5, k + 0, GCCoreBlocks.decorationBlocks.blockID, 4, 3);
		world.setBlockAndMetadataWithNotify(i + 11, j + 5, k + 6, GCCoreBlocks.decorationBlocks.blockID, 4, 3);
		world.setBlockAndMetadataWithNotify(i + 11, j + 6, k + 0, GCCoreBlocks.decorationBlocks.blockID, 4, 3);
		world.setBlockAndMetadataWithNotify(i + 11, j + 6, k + 1, GCCoreBlocks.decorationBlocks.blockID, 4, 3);
		world.setBlockAndMetadataWithNotify(i + 11, j + 6, k + 2, GCCoreBlocks.decorationBlocks.blockID, 4, 3);
		world.setBlockAndMetadataWithNotify(i + 11, j + 6, k + 3, GCCoreBlocks.decorationBlocks.blockID, 4, 3);
		world.setBlockAndMetadataWithNotify(i + 11, j + 6, k + 4, GCCoreBlocks.decorationBlocks.blockID, 4, 3);
		world.setBlockAndMetadataWithNotify(i + 11, j + 6, k + 5, GCCoreBlocks.decorationBlocks.blockID, 4, 3);
		world.setBlockAndMetadataWithNotify(i + 11, j + 6, k + 6, GCCoreBlocks.decorationBlocks.blockID, 4, 3);
		world.setBlockAndMetadataWithNotify(i + 12, j + 1, k + 0, GCCoreBlocks.decorationBlocks.blockID, 4, 3);
		world.setBlockAndMetadataWithNotify(i + 12, j + 1, k + 1, GCCoreBlocks.decorationBlocks.blockID, 4, 3);
		world.setBlockAndMetadataWithNotify(i + 12, j + 1, k + 2, GCCoreBlocks.decorationBlocks.blockID, 4, 3);
		world.setBlockAndMetadataWithNotify(i + 12, j + 1, k + 3, GCCoreBlocks.decorationBlocks.blockID, 4, 3);
		world.setBlockAndMetadataWithNotify(i + 12, j + 1, k + 4, GCCoreBlocks.decorationBlocks.blockID, 4, 3);
		world.setBlockAndMetadataWithNotify(i + 12, j + 1, k + 5, GCCoreBlocks.decorationBlocks.blockID, 4, 3);
		world.setBlockAndMetadataWithNotify(i + 12, j + 1, k + 6, GCCoreBlocks.decorationBlocks.blockID, 4, 3);
		world.setBlockAndMetadataWithNotify(i + 12, j + 2, k + 0, GCCoreBlocks.decorationBlocks.blockID, 4, 3);
		world.setBlockAndMetadataWithNotify(i + 12, j + 2, k + 6, GCCoreBlocks.decorationBlocks.blockID, 4, 3);
		world.setBlockAndMetadataWithNotify(i + 12, j + 3, k + 0, 102, 0, 3);
		world.setBlockAndMetadataWithNotify(i + 12, j + 3, k + 6, 102, 0, 3);
		world.setBlockAndMetadataWithNotify(i + 12, j + 4, k + 0, GCCoreBlocks.decorationBlocks.blockID, 4, 3);
		world.setBlockAndMetadataWithNotify(i + 12, j + 4, k + 6, GCCoreBlocks.decorationBlocks.blockID, 4, 3);
		world.setBlockAndMetadataWithNotify(i + 12, j + 5, k + 0, GCCoreBlocks.decorationBlocks.blockID, 4, 3);
		world.setBlockAndMetadataWithNotify(i + 12, j + 5, k + 6, GCCoreBlocks.decorationBlocks.blockID, 4, 3);
		world.setBlockAndMetadataWithNotify(i + 12, j + 6, k + 0, GCCoreBlocks.decorationBlocks.blockID, 4, 3);
		world.setBlockAndMetadataWithNotify(i + 12, j + 6, k + 1, GCCoreBlocks.decorationBlocks.blockID, 4, 3);
		world.setBlockAndMetadataWithNotify(i + 12, j + 6, k + 2, GCCoreBlocks.decorationBlocks.blockID, 4, 3);
		world.setBlockAndMetadataWithNotify(i + 12, j + 6, k + 3, GCCoreBlocks.decorationBlocks.blockID, 4, 3);
		world.setBlockAndMetadataWithNotify(i + 12, j + 6, k + 4, GCCoreBlocks.decorationBlocks.blockID, 4, 3);
		world.setBlockAndMetadataWithNotify(i + 12, j + 6, k + 5, GCCoreBlocks.decorationBlocks.blockID, 4, 3);
		world.setBlockAndMetadataWithNotify(i + 12, j + 6, k + 6, GCCoreBlocks.decorationBlocks.blockID, 4, 3);
		world.setBlockAndMetadataWithNotify(i + 13, j + 1, k + 0, GCCoreBlocks.decorationBlocks.blockID, 4, 3);
		world.setBlockAndMetadataWithNotify(i + 13, j + 1, k + 1, GCCoreBlocks.decorationBlocks.blockID, 4, 3);
		world.setBlockAndMetadataWithNotify(i + 13, j + 1, k + 2, GCCoreBlocks.decorationBlocks.blockID, 4, 3);
		world.setBlockAndMetadataWithNotify(i + 13, j + 1, k + 3, GCCoreBlocks.decorationBlocks.blockID, 4, 3);
		world.setBlockAndMetadataWithNotify(i + 13, j + 1, k + 4, GCCoreBlocks.decorationBlocks.blockID, 4, 3);
		world.setBlockAndMetadataWithNotify(i + 13, j + 1, k + 5, GCCoreBlocks.decorationBlocks.blockID, 4, 3);
		world.setBlockAndMetadataWithNotify(i + 13, j + 1, k + 6, GCCoreBlocks.decorationBlocks.blockID, 4, 3);
		world.setBlockAndMetadataWithNotify(i + 13, j + 2, k + 0, GCCoreBlocks.decorationBlocks.blockID, 4, 3);
		world.setBlockAndMetadataWithNotify(i + 13, j + 2, k + 1, GCCoreBlocks.decorationBlocks.blockID, 4, 3);
		world.setBlockAndMetadataWithNotify(i + 13, j + 2, k + 5, GCCoreBlocks.decorationBlocks.blockID, 4, 3);
		world.setBlockAndMetadataWithNotify(i + 13, j + 2, k + 6, GCCoreBlocks.decorationBlocks.blockID, 4, 3);
		world.setBlockAndMetadataWithNotify(i + 13, j + 3, k + 0, GCCoreBlocks.decorationBlocks.blockID, 4, 3);
		world.setBlockAndMetadataWithNotify(i + 13, j + 3, k + 1, 102, 0, 3);
		world.setBlockAndMetadataWithNotify(i + 13, j + 3, k + 5, 102, 0, 3);
		world.setBlockAndMetadataWithNotify(i + 13, j + 3, k + 6, GCCoreBlocks.decorationBlocks.blockID, 4, 3);
		world.setBlockAndMetadataWithNotify(i + 13, j + 4, k + 0, GCCoreBlocks.decorationBlocks.blockID, 4, 3);
		world.setBlockAndMetadataWithNotify(i + 13, j + 4, k + 1, GCCoreBlocks.decorationBlocks.blockID, 4, 3);
		world.setBlockAndMetadataWithNotify(i + 13, j + 4, k + 5, GCCoreBlocks.decorationBlocks.blockID, 4, 3);
		world.setBlockAndMetadataWithNotify(i + 13, j + 4, k + 6, GCCoreBlocks.decorationBlocks.blockID, 4, 3);
		world.setBlockAndMetadataWithNotify(i + 13, j + 5, k + 0, GCCoreBlocks.decorationBlocks.blockID, 4, 3);
		world.setBlockAndMetadataWithNotify(i + 13, j + 5, k + 1, GCCoreBlocks.decorationBlocks.blockID, 4, 3);
		world.setBlockAndMetadataWithNotify(i + 13, j + 5, k + 2, GCCoreBlocks.decorationBlocks.blockID, 4, 3);
		world.setBlockAndMetadataWithNotify(i + 13, j + 5, k + 3, GCCoreBlocks.decorationBlocks.blockID, 4, 3);
		world.setBlockAndMetadataWithNotify(i + 13, j + 5, k + 4, GCCoreBlocks.decorationBlocks.blockID, 4, 3);
		world.setBlockAndMetadataWithNotify(i + 13, j + 5, k + 5, GCCoreBlocks.decorationBlocks.blockID, 4, 3);
		world.setBlockAndMetadataWithNotify(i + 13, j + 5, k + 6, GCCoreBlocks.decorationBlocks.blockID, 4, 3);
		world.setBlockAndMetadataWithNotify(i + 13, j + 6, k + 0, GCCoreBlocks.decorationBlocks.blockID, 4, 3);
		world.setBlockAndMetadataWithNotify(i + 13, j + 6, k + 1, GCCoreBlocks.decorationBlocks.blockID, 4, 3);
		world.setBlockAndMetadataWithNotify(i + 13, j + 6, k + 2, GCCoreBlocks.decorationBlocks.blockID, 4, 3);
		world.setBlockAndMetadataWithNotify(i + 13, j + 6, k + 3, GCCoreBlocks.decorationBlocks.blockID, 4, 3);
		world.setBlockAndMetadataWithNotify(i + 13, j + 6, k + 4, GCCoreBlocks.decorationBlocks.blockID, 4, 3);
		world.setBlockAndMetadataWithNotify(i + 13, j + 6, k + 5, GCCoreBlocks.decorationBlocks.blockID, 4, 3);
		world.setBlockAndMetadataWithNotify(i + 13, j + 6, k + 6, GCCoreBlocks.decorationBlocks.blockID, 4, 3);

		return true;
	}
}