/*
*** MADE BY MITHION'S .SCHEMATIC TO JAVA CONVERTING TOOL v1.6 ***
*/

package micdoodle8.mods.galacticraft.mars;

import java.util.Random;
import net.minecraft.src.Block;
import net.minecraft.src.WorldGenerator;
import net.minecraft.src.World;

public class GCMarsWorldGenCreeperNest extends WorldGenerator
{
	private int id = GCMarsBlocks.creeperDungeonWall.blockID;

	public boolean generate(World world, Random rand, int i, int j, int k) {
		world.setBlock(i + 0, j + 19, k + 0, id);
		world.setBlock(i + 0, j + 19, k + 1, id);
		world.setBlock(i + 0, j + 19, k + 2, id);
		world.setBlock(i + 0, j + 19, k + 3, id);
		world.setBlock(i + 0, j + 19, k + 4, id);
		world.setBlock(i + 0, j + 19, k + 5, id);
		world.setBlock(i + 0, j + 19, k + 6, id);
		world.setBlock(i + 0, j + 19, k + 7, id);
		world.setBlock(i + 0, j + 19, k + 8, id);
		world.setBlock(i + 0, j + 19, k + 9, id);
		world.setBlock(i + 0, j + 19, k + 10, id);
		world.setBlock(i + 0, j + 19, k + 11, id);
		world.setBlock(i + 0, j + 19, k + 12, id);
		world.setBlock(i + 0, j + 19, k + 13, id);
		world.setBlock(i + 0, j + 19, k + 14, id);
		world.setBlock(i + 0, j + 19, k + 15, id);
		world.setBlock(i + 0, j + 19, k + 16, id);
		world.setBlock(i + 0, j + 19, k + 17, id);
		world.setBlock(i + 0, j + 19, k + 18, id);
		world.setBlock(i + 0, j + 19, k + 19, id);
		world.setBlock(i + 0, j + 19, k + 20, id);
		world.setBlock(i + 0, j + 19, k + 21, id);
		world.setBlock(i + 0, j + 19, k + 22, id);
		world.setBlock(i + 0, j + 19, k + 23, id);
		world.setBlock(i + 0, j + 19, k + 24, id);
		world.setBlock(i + 0, j + 19, k + 25, id);
		world.setBlock(i + 0, j + 19, k + 26, id);
		world.setBlock(i + 0, j + 19, k + 27, id);
		world.setBlock(i + 0, j + 19, k + 28, id);
		world.setBlock(i + 0, j + 19, k + 29, id);
		world.setBlock(i + 0, j + 19, k + 30, id);
		world.setBlock(i + 0, j + 19, k + 31, id);
		world.setBlock(i + 0, j + 19, k + 32, id);
		world.setBlock(i + 0, j + 19, k + 33, id);
		world.setBlock(i + 0, j + 19, k + 34, id);
		world.setBlock(i + 0, j + 19, k + 35, id);
		world.setBlock(i + 0, j + 19, k + 36, id);
		world.setBlock(i + 0, j + 19, k + 37, id);
		world.setBlock(i + 0, j + 19, k + 38, id);
		world.setBlock(i + 0, j + 19, k + 39, id);
		world.setBlock(i + 0, j + 19, k + 40, id);
		world.setBlock(i + 0, j + 19, k + 41, id);
		world.setBlock(i + 0, j + 19, k + 42, id);
		world.setBlock(i + 0, j + 19, k + 43, id);
		world.setBlock(i + 0, j + 19, k + 44, id);
		world.setBlock(i + 0, j + 19, k + 45, id);
		world.setBlock(i + 0, j + 19, k + 46, id);
		world.setBlock(i + 0, j + 19, k + 47, id);
		world.setBlock(i + 0, j + 19, k + 48, id);
		world.setBlock(i + 0, j + 19, k + 49, id);
		world.setBlock(i + 0, j + 19, k + 50, id);
		world.setBlock(i + 0, j + 19, k + 51, id);
		world.setBlock(i + 0, j + 19, k + 52, id);
		world.setBlock(i + 0, j + 19, k + 53, id);
		world.setBlock(i + 0, j + 19, k + 54, id);
		world.setBlock(i + 0, j + 19, k + 55, id);
		world.setBlock(i + 0, j + 19, k + 56, id);
		world.setBlock(i + 0, j + 19, k + 57, id);
		world.setBlock(i + 0, j + 19, k + 58, id);
		world.setBlock(i + 0, j + 19, k + 59, id);
		world.setBlock(i + 0, j + 19, k + 60, id);
		world.setBlock(i + 0, j + 19, k + 61, id);
		world.setBlock(i + 0, j + 19, k + 62, id);
		world.setBlock(i + 0, j + 19, k + 63, id);
		world.setBlock(i + 0, j + 19, k + 64, id);
		world.setBlock(i + 0, j + 19, k + 65, id);
		world.setBlock(i + 0, j + 19, k + 66, id);
		world.setBlock(i + 0, j + 19, k + 67, id);
		world.setBlock(i + 0, j + 19, k + 68, id);
		world.setBlock(i + 0, j + 19, k + 69, id);
		world.setBlock(i + 0, j + 19, k + 70, id);
		world.setBlock(i + 0, j + 19, k + 71, id);
		world.setBlock(i + 0, j + 19, k + 72, id);
		world.setBlock(i + 0, j + 19, k + 73, id);
		world.setBlock(i + 0, j + 19, k + 74, id);
		world.setBlock(i + 0, j + 19, k + 75, id);
		world.setBlock(i + 0, j + 19, k + 76, id);
		world.setBlock(i + 0, j + 19, k + 77, id);
		world.setBlock(i + 0, j + 19, k + 78, id);
		world.setBlock(i + 0, j + 19, k + 79, id);
		world.setBlock(i + 0, j + 20, k + 0, id);
		world.setBlock(i + 0, j + 20, k + 1, id);
		world.setBlock(i + 0, j + 20, k + 2, id);
		world.setBlock(i + 0, j + 20, k + 3, id);
		world.setBlock(i + 0, j + 20, k + 4, id);
		world.setBlock(i + 0, j + 20, k + 5, id);
		world.setBlock(i + 0, j + 20, k + 6, id);
		world.setBlock(i + 0, j + 20, k + 7, id);
		world.setBlock(i + 0, j + 20, k + 8, id);
		world.setBlock(i + 0, j + 20, k + 9, id);
		world.setBlock(i + 0, j + 20, k + 10, id);
		world.setBlock(i + 0, j + 20, k + 11, id);
		world.setBlock(i + 0, j + 20, k + 12, id);
		world.setBlock(i + 0, j + 20, k + 13, id);
		world.setBlock(i + 0, j + 20, k + 14, id);
		world.setBlock(i + 0, j + 20, k + 15, id);
		world.setBlock(i + 0, j + 20, k + 16, id);
		world.setBlock(i + 0, j + 20, k + 17, id);
		world.setBlock(i + 0, j + 20, k + 18, id);
		world.setBlock(i + 0, j + 20, k + 19, id);
		world.setBlock(i + 0, j + 20, k + 20, id);
		world.setBlock(i + 0, j + 20, k + 21, id);
		world.setBlock(i + 0, j + 20, k + 22, id);
		world.setBlock(i + 0, j + 20, k + 23, id);
		world.setBlock(i + 0, j + 20, k + 24, id);
		world.setBlock(i + 0, j + 20, k + 25, id);
		world.setBlock(i + 0, j + 20, k + 26, id);
		world.setBlock(i + 0, j + 20, k + 27, id);
		world.setBlock(i + 0, j + 20, k + 28, id);
		world.setBlock(i + 0, j + 20, k + 29, id);
		world.setBlock(i + 0, j + 20, k + 30, id);
		world.setBlock(i + 0, j + 20, k + 31, id);
		world.setBlock(i + 0, j + 20, k + 32, id);
		world.setBlock(i + 0, j + 20, k + 33, id);
		world.setBlock(i + 0, j + 20, k + 34, id);
		world.setBlock(i + 0, j + 20, k + 35, id);
		world.setBlock(i + 0, j + 20, k + 36, id);
		world.setBlock(i + 0, j + 20, k + 37, id);
		world.setBlock(i + 0, j + 20, k + 38, id);
		world.setBlock(i + 0, j + 20, k + 39, id);
		world.setBlock(i + 0, j + 20, k + 40, id);
		world.setBlock(i + 0, j + 20, k + 41, id);
		world.setBlock(i + 0, j + 20, k + 42, id);
		world.setBlock(i + 0, j + 20, k + 43, id);
		world.setBlock(i + 0, j + 20, k + 44, id);
		world.setBlock(i + 0, j + 20, k + 45, id);
		world.setBlock(i + 0, j + 20, k + 46, id);
		world.setBlock(i + 0, j + 20, k + 47, id);
		world.setBlock(i + 0, j + 20, k + 48, id);
		world.setBlock(i + 0, j + 20, k + 49, id);
		world.setBlock(i + 0, j + 20, k + 50, id);
		world.setBlock(i + 0, j + 20, k + 51, id);
		world.setBlock(i + 0, j + 20, k + 52, id);
		world.setBlock(i + 0, j + 20, k + 53, id);
		world.setBlock(i + 0, j + 20, k + 54, id);
		world.setBlock(i + 0, j + 20, k + 55, id);
		world.setBlock(i + 0, j + 20, k + 56, id);
		world.setBlock(i + 0, j + 20, k + 57, id);
		world.setBlock(i + 0, j + 20, k + 58, id);
		world.setBlock(i + 0, j + 20, k + 59, id);
		world.setBlock(i + 0, j + 20, k + 60, id);
		world.setBlock(i + 0, j + 20, k + 61, id);
		world.setBlock(i + 0, j + 20, k + 62, id);
		world.setBlock(i + 0, j + 20, k + 63, id);
		world.setBlock(i + 0, j + 20, k + 64, id);
		world.setBlock(i + 0, j + 20, k + 65, id);
		world.setBlock(i + 0, j + 20, k + 66, id);
		world.setBlock(i + 0, j + 20, k + 67, id);
		world.setBlock(i + 0, j + 20, k + 68, id);
		world.setBlock(i + 0, j + 20, k + 69, id);
		world.setBlock(i + 0, j + 20, k + 70, id);
		world.setBlock(i + 0, j + 20, k + 71, id);
		world.setBlock(i + 0, j + 20, k + 72, id);
		world.setBlock(i + 0, j + 20, k + 73, id);
		world.setBlock(i + 0, j + 20, k + 74, id);
		world.setBlock(i + 0, j + 20, k + 75, id);
		world.setBlock(i + 0, j + 20, k + 76, id);
		world.setBlock(i + 0, j + 20, k + 77, id);
		world.setBlock(i + 0, j + 20, k + 78, id);
		world.setBlock(i + 0, j + 20, k + 79, id);
		world.setBlock(i + 0, j + 21, k + 0, id);
		world.setBlock(i + 0, j + 21, k + 1, id);
		world.setBlock(i + 0, j + 21, k + 2, id);
		world.setBlock(i + 0, j + 21, k + 3, id);
		world.setBlock(i + 0, j + 21, k + 4, id);
		world.setBlock(i + 0, j + 21, k + 5, id);
		world.setBlock(i + 0, j + 21, k + 6, id);
		world.setBlock(i + 0, j + 21, k + 7, id);
		world.setBlock(i + 0, j + 21, k + 8, id);
		world.setBlock(i + 0, j + 21, k + 9, id);
		world.setBlock(i + 0, j + 21, k + 10, id);
		world.setBlock(i + 0, j + 21, k + 11, id);
		world.setBlock(i + 0, j + 21, k + 12, id);
		world.setBlock(i + 0, j + 21, k + 13, id);
		world.setBlock(i + 0, j + 21, k + 14, id);
		world.setBlock(i + 0, j + 21, k + 15, id);
		world.setBlock(i + 0, j + 21, k + 16, id);
		world.setBlock(i + 0, j + 21, k + 17, id);
		world.setBlock(i + 0, j + 21, k + 18, id);
		world.setBlock(i + 0, j + 21, k + 19, id);
		world.setBlock(i + 0, j + 21, k + 20, id);
		world.setBlock(i + 0, j + 21, k + 21, id);
		world.setBlock(i + 0, j + 21, k + 22, id);
		world.setBlock(i + 0, j + 21, k + 23, id);
		world.setBlock(i + 0, j + 21, k + 24, id);
		world.setBlock(i + 0, j + 21, k + 25, id);
		world.setBlock(i + 0, j + 21, k + 26, id);
		world.setBlock(i + 0, j + 21, k + 27, id);
		world.setBlock(i + 0, j + 21, k + 28, id);
		world.setBlock(i + 0, j + 21, k + 29, id);
		world.setBlock(i + 0, j + 21, k + 30, id);
		world.setBlock(i + 0, j + 21, k + 31, id);
		world.setBlock(i + 0, j + 21, k + 32, id);
		world.setBlock(i + 0, j + 21, k + 33, id);
		world.setBlock(i + 0, j + 21, k + 34, id);
		world.setBlock(i + 0, j + 21, k + 35, id);
		world.setBlock(i + 0, j + 21, k + 36, id);
		world.setBlock(i + 0, j + 21, k + 37, id);
		world.setBlock(i + 0, j + 21, k + 38, id);
		world.setBlock(i + 0, j + 21, k + 39, id);
		world.setBlock(i + 0, j + 21, k + 40, id);
		world.setBlock(i + 0, j + 21, k + 41, id);
		world.setBlock(i + 0, j + 21, k + 42, id);
		world.setBlock(i + 0, j + 21, k + 43, id);
		world.setBlock(i + 0, j + 21, k + 44, id);
		world.setBlock(i + 0, j + 21, k + 45, id);
		world.setBlock(i + 0, j + 21, k + 46, id);
		world.setBlock(i + 0, j + 21, k + 47, id);
		world.setBlock(i + 0, j + 21, k + 48, id);
		world.setBlock(i + 0, j + 21, k + 49, id);
		world.setBlock(i + 0, j + 21, k + 50, id);
		world.setBlock(i + 0, j + 21, k + 51, id);
		world.setBlock(i + 0, j + 21, k + 52, id);
		world.setBlock(i + 0, j + 21, k + 53, id);
		world.setBlock(i + 0, j + 21, k + 54, id);
		world.setBlock(i + 0, j + 21, k + 55, id);
		world.setBlock(i + 0, j + 21, k + 56, id);
		world.setBlock(i + 0, j + 21, k + 57, id);
		world.setBlock(i + 0, j + 21, k + 58, id);
		world.setBlock(i + 0, j + 21, k + 59, id);
		world.setBlock(i + 0, j + 21, k + 60, id);
		world.setBlock(i + 0, j + 21, k + 61, id);
		world.setBlock(i + 0, j + 21, k + 62, id);
		world.setBlock(i + 0, j + 21, k + 63, id);
		world.setBlock(i + 0, j + 21, k + 64, id);
		world.setBlock(i + 0, j + 21, k + 65, id);
		world.setBlock(i + 0, j + 21, k + 66, id);
		world.setBlock(i + 0, j + 21, k + 67, id);
		world.setBlock(i + 0, j + 21, k + 68, id);
		world.setBlock(i + 0, j + 21, k + 69, id);
		world.setBlock(i + 0, j + 21, k + 70, id);
		world.setBlock(i + 0, j + 21, k + 71, id);
		world.setBlock(i + 0, j + 21, k + 72, id);
		world.setBlock(i + 0, j + 21, k + 73, id);
		world.setBlock(i + 0, j + 21, k + 74, id);
		world.setBlock(i + 0, j + 21, k + 75, id);
		world.setBlock(i + 0, j + 21, k + 76, id);
		world.setBlock(i + 0, j + 21, k + 77, id);
		world.setBlock(i + 0, j + 21, k + 78, id);
		world.setBlock(i + 0, j + 21, k + 79, id);
		world.setBlock(i + 0, j + 22, k + 0, id);
		world.setBlock(i + 0, j + 22, k + 1, id);
		world.setBlock(i + 0, j + 22, k + 2, id);
		world.setBlock(i + 0, j + 22, k + 3, id);
		world.setBlock(i + 0, j + 22, k + 4, id);
		world.setBlock(i + 0, j + 22, k + 5, id);
		world.setBlock(i + 0, j + 22, k + 6, id);
		world.setBlock(i + 0, j + 22, k + 7, id);
		world.setBlock(i + 0, j + 22, k + 8, id);
		world.setBlock(i + 0, j + 22, k + 9, id);
		world.setBlock(i + 0, j + 22, k + 10, id);
		world.setBlock(i + 0, j + 22, k + 11, id);
		world.setBlock(i + 0, j + 22, k + 12, id);
		world.setBlock(i + 0, j + 22, k + 13, id);
		world.setBlock(i + 0, j + 22, k + 14, id);
		world.setBlock(i + 0, j + 22, k + 15, id);
		world.setBlock(i + 0, j + 22, k + 16, id);
		world.setBlock(i + 0, j + 22, k + 17, id);
		world.setBlock(i + 0, j + 22, k + 18, id);
		world.setBlock(i + 0, j + 22, k + 19, id);
		world.setBlock(i + 0, j + 22, k + 20, id);
		world.setBlock(i + 0, j + 22, k + 21, id);
		world.setBlock(i + 0, j + 22, k + 22, id);
		world.setBlock(i + 0, j + 22, k + 23, id);
		world.setBlock(i + 0, j + 22, k + 24, id);
		world.setBlock(i + 0, j + 22, k + 25, id);
		world.setBlock(i + 0, j + 22, k + 26, id);
		world.setBlock(i + 0, j + 22, k + 27, id);
		world.setBlock(i + 0, j + 22, k + 28, id);
		world.setBlock(i + 0, j + 22, k + 29, id);
		world.setBlock(i + 0, j + 22, k + 30, id);
		world.setBlock(i + 0, j + 22, k + 31, id);
		world.setBlock(i + 0, j + 22, k + 32, id);
		world.setBlock(i + 0, j + 22, k + 33, id);
		world.setBlock(i + 0, j + 22, k + 34, id);
		world.setBlock(i + 0, j + 22, k + 35, id);
		world.setBlock(i + 0, j + 22, k + 36, id);
		world.setBlock(i + 0, j + 22, k + 37, id);
		world.setBlock(i + 0, j + 22, k + 38, id);
		world.setBlock(i + 0, j + 22, k + 39, id);
		world.setBlock(i + 0, j + 22, k + 40, id);
		world.setBlock(i + 0, j + 22, k + 41, id);
		world.setBlock(i + 0, j + 22, k + 42, id);
		world.setBlock(i + 0, j + 22, k + 43, id);
		world.setBlock(i + 0, j + 22, k + 44, id);
		world.setBlock(i + 0, j + 22, k + 45, id);
		world.setBlock(i + 0, j + 22, k + 46, id);
		world.setBlock(i + 0, j + 22, k + 47, id);
		world.setBlock(i + 0, j + 22, k + 48, id);
		world.setBlock(i + 0, j + 22, k + 49, id);
		world.setBlock(i + 0, j + 22, k + 50, id);
		world.setBlock(i + 0, j + 22, k + 51, id);
		world.setBlock(i + 0, j + 22, k + 52, id);
		world.setBlock(i + 0, j + 22, k + 53, id);
		world.setBlock(i + 0, j + 22, k + 54, id);
		world.setBlock(i + 0, j + 22, k + 55, id);
		world.setBlock(i + 0, j + 22, k + 56, id);
		world.setBlock(i + 0, j + 22, k + 57, id);
		world.setBlock(i + 0, j + 22, k + 58, id);
		world.setBlock(i + 0, j + 22, k + 59, id);
		world.setBlock(i + 0, j + 22, k + 60, id);
		world.setBlock(i + 0, j + 22, k + 61, id);
		world.setBlock(i + 0, j + 22, k + 62, id);
		world.setBlock(i + 0, j + 22, k + 63, id);
		world.setBlock(i + 0, j + 22, k + 64, id);
		world.setBlock(i + 0, j + 22, k + 65, id);
		world.setBlock(i + 0, j + 22, k + 66, id);
		world.setBlock(i + 0, j + 22, k + 67, id);
		world.setBlock(i + 0, j + 22, k + 68, id);
		world.setBlock(i + 0, j + 22, k + 69, id);
		world.setBlock(i + 0, j + 22, k + 70, id);
		world.setBlock(i + 0, j + 22, k + 71, id);
		world.setBlock(i + 0, j + 22, k + 72, id);
		world.setBlock(i + 0, j + 22, k + 73, id);
		world.setBlock(i + 0, j + 22, k + 74, id);
		world.setBlock(i + 0, j + 22, k + 75, id);
		world.setBlock(i + 0, j + 22, k + 76, id);
		world.setBlock(i + 0, j + 22, k + 77, id);
		world.setBlock(i + 0, j + 22, k + 78, id);
		world.setBlock(i + 0, j + 22, k + 79, id);
		world.setBlock(i + 0, j + 23, k + 0, id);
		world.setBlock(i + 0, j + 23, k + 1, id);
		world.setBlock(i + 0, j + 23, k + 2, id);
		world.setBlock(i + 0, j + 23, k + 3, id);
		world.setBlock(i + 0, j + 23, k + 4, id);
		world.setBlock(i + 0, j + 23, k + 5, id);
		world.setBlock(i + 0, j + 23, k + 6, id);
		world.setBlock(i + 0, j + 23, k + 7, id);
		world.setBlock(i + 0, j + 23, k + 8, id);
		world.setBlock(i + 0, j + 23, k + 9, id);
		world.setBlock(i + 0, j + 23, k + 10, id);
		world.setBlock(i + 0, j + 23, k + 11, id);
		world.setBlock(i + 0, j + 23, k + 12, id);
		world.setBlock(i + 0, j + 23, k + 13, id);
		world.setBlock(i + 0, j + 23, k + 14, id);
		world.setBlock(i + 0, j + 23, k + 15, id);
		world.setBlock(i + 0, j + 23, k + 16, id);
		world.setBlock(i + 0, j + 23, k + 17, id);
		world.setBlock(i + 0, j + 23, k + 18, id);
		world.setBlock(i + 0, j + 23, k + 19, id);
		world.setBlock(i + 0, j + 23, k + 20, id);
		world.setBlock(i + 0, j + 23, k + 21, id);
		world.setBlock(i + 0, j + 23, k + 22, id);
		world.setBlock(i + 0, j + 23, k + 23, id);
		world.setBlock(i + 0, j + 23, k + 24, id);
		world.setBlock(i + 0, j + 23, k + 25, id);
		world.setBlock(i + 0, j + 23, k + 26, id);
		world.setBlock(i + 0, j + 23, k + 27, id);
		world.setBlock(i + 0, j + 23, k + 28, id);
		world.setBlock(i + 0, j + 23, k + 29, id);
		world.setBlock(i + 0, j + 23, k + 30, id);
		world.setBlock(i + 0, j + 23, k + 31, id);
		world.setBlock(i + 0, j + 23, k + 32, id);
		world.setBlock(i + 0, j + 23, k + 33, id);
		world.setBlock(i + 0, j + 23, k + 34, id);
		world.setBlock(i + 0, j + 23, k + 35, id);
		world.setBlock(i + 0, j + 23, k + 36, id);
		world.setBlock(i + 0, j + 23, k + 37, id);
		world.setBlock(i + 0, j + 23, k + 38, id);
		world.setBlock(i + 0, j + 23, k + 39, id);
		world.setBlock(i + 0, j + 23, k + 40, id);
		world.setBlock(i + 0, j + 23, k + 41, id);
		world.setBlock(i + 0, j + 23, k + 42, id);
		world.setBlock(i + 0, j + 23, k + 43, id);
		world.setBlock(i + 0, j + 23, k + 44, id);
		world.setBlock(i + 0, j + 23, k + 45, id);
		world.setBlock(i + 0, j + 23, k + 46, id);
		world.setBlock(i + 0, j + 23, k + 47, id);
		world.setBlock(i + 0, j + 23, k + 48, id);
		world.setBlock(i + 0, j + 23, k + 49, id);
		world.setBlock(i + 0, j + 23, k + 50, id);
		world.setBlock(i + 0, j + 23, k + 51, id);
		world.setBlock(i + 0, j + 23, k + 52, id);
		world.setBlock(i + 0, j + 23, k + 53, id);
		world.setBlock(i + 0, j + 23, k + 54, id);
		world.setBlock(i + 0, j + 23, k + 55, id);
		world.setBlock(i + 0, j + 23, k + 56, id);
		world.setBlock(i + 0, j + 23, k + 57, id);
		world.setBlock(i + 0, j + 23, k + 58, id);
		world.setBlock(i + 0, j + 23, k + 59, id);
		world.setBlock(i + 0, j + 23, k + 60, id);
		world.setBlock(i + 0, j + 23, k + 61, id);
		world.setBlock(i + 0, j + 23, k + 62, id);
		world.setBlock(i + 0, j + 23, k + 63, id);
		world.setBlock(i + 0, j + 23, k + 64, id);
		world.setBlock(i + 0, j + 23, k + 65, id);
		world.setBlock(i + 0, j + 23, k + 66, id);
		world.setBlock(i + 0, j + 23, k + 67, id);
		world.setBlock(i + 0, j + 23, k + 68, id);
		world.setBlock(i + 0, j + 23, k + 69, id);
		world.setBlock(i + 0, j + 23, k + 70, id);
		world.setBlock(i + 0, j + 23, k + 71, id);
		world.setBlock(i + 0, j + 23, k + 72, id);
		world.setBlock(i + 0, j + 23, k + 73, id);
		world.setBlock(i + 0, j + 23, k + 74, id);
		world.setBlock(i + 0, j + 23, k + 75, id);
		world.setBlock(i + 0, j + 23, k + 76, id);
		world.setBlock(i + 0, j + 23, k + 77, id);
		world.setBlock(i + 0, j + 23, k + 78, id);
		world.setBlock(i + 0, j + 23, k + 79, id);
		world.setBlock(i + 0, j + 24, k + 0, id);
		world.setBlock(i + 0, j + 24, k + 1, id);
		world.setBlock(i + 0, j + 24, k + 2, id);
		world.setBlock(i + 0, j + 24, k + 3, id);
		world.setBlock(i + 0, j + 24, k + 4, id);
		world.setBlock(i + 0, j + 24, k + 5, id);
		world.setBlock(i + 0, j + 24, k + 6, id);
		world.setBlock(i + 0, j + 24, k + 7, id);
		world.setBlock(i + 0, j + 24, k + 8, id);
		world.setBlock(i + 0, j + 24, k + 9, id);
		world.setBlock(i + 0, j + 24, k + 10, id);
		world.setBlock(i + 0, j + 24, k + 11, id);
		world.setBlock(i + 0, j + 24, k + 12, id);
		world.setBlock(i + 0, j + 24, k + 13, id);
		world.setBlock(i + 0, j + 24, k + 14, id);
		world.setBlock(i + 0, j + 24, k + 15, id);
		world.setBlock(i + 0, j + 24, k + 16, id);
		world.setBlock(i + 0, j + 24, k + 17, id);
		world.setBlock(i + 0, j + 24, k + 18, id);
		world.setBlock(i + 0, j + 24, k + 19, id);
		world.setBlock(i + 0, j + 24, k + 20, id);
		world.setBlock(i + 0, j + 24, k + 21, id);
		world.setBlock(i + 0, j + 24, k + 22, id);
		world.setBlock(i + 0, j + 24, k + 23, id);
		world.setBlock(i + 0, j + 24, k + 24, id);
		world.setBlock(i + 0, j + 24, k + 25, id);
		world.setBlock(i + 0, j + 24, k + 26, id);
		world.setBlock(i + 0, j + 24, k + 27, id);
		world.setBlock(i + 0, j + 24, k + 28, id);
		world.setBlock(i + 0, j + 24, k + 29, id);
		world.setBlock(i + 0, j + 24, k + 30, id);
		world.setBlock(i + 0, j + 24, k + 31, id);
		world.setBlock(i + 0, j + 24, k + 32, id);
		world.setBlock(i + 0, j + 24, k + 33, id);
		world.setBlock(i + 0, j + 24, k + 34, id);
		world.setBlock(i + 0, j + 24, k + 35, id);
		world.setBlock(i + 0, j + 24, k + 36, id);
		world.setBlock(i + 0, j + 24, k + 37, id);
		world.setBlock(i + 0, j + 24, k + 38, id);
		world.setBlock(i + 0, j + 24, k + 39, id);
		world.setBlock(i + 0, j + 24, k + 40, id);
		world.setBlock(i + 0, j + 24, k + 41, id);
		world.setBlock(i + 0, j + 24, k + 42, id);
		world.setBlock(i + 0, j + 24, k + 43, id);
		world.setBlock(i + 0, j + 24, k + 44, id);
		world.setBlock(i + 0, j + 24, k + 45, id);
		world.setBlock(i + 0, j + 24, k + 46, id);
		world.setBlock(i + 0, j + 24, k + 47, id);
		world.setBlock(i + 0, j + 24, k + 48, id);
		world.setBlock(i + 0, j + 24, k + 49, id);
		world.setBlock(i + 0, j + 24, k + 50, id);
		world.setBlock(i + 0, j + 24, k + 51, id);
		world.setBlock(i + 0, j + 24, k + 52, id);
		world.setBlock(i + 0, j + 24, k + 53, id);
		world.setBlock(i + 0, j + 24, k + 54, id);
		world.setBlock(i + 0, j + 24, k + 55, id);
		world.setBlock(i + 0, j + 24, k + 56, id);
		world.setBlock(i + 0, j + 24, k + 57, id);
		world.setBlock(i + 0, j + 24, k + 58, id);
		world.setBlock(i + 0, j + 24, k + 59, id);
		world.setBlock(i + 0, j + 24, k + 60, id);
		world.setBlock(i + 0, j + 24, k + 61, id);
		world.setBlock(i + 0, j + 24, k + 62, id);
		world.setBlock(i + 0, j + 24, k + 63, id);
		world.setBlock(i + 0, j + 24, k + 64, id);
		world.setBlock(i + 0, j + 24, k + 65, id);
		world.setBlock(i + 0, j + 24, k + 66, id);
		world.setBlock(i + 0, j + 24, k + 67, id);
		world.setBlock(i + 0, j + 24, k + 68, id);
		world.setBlock(i + 0, j + 24, k + 69, id);
		world.setBlock(i + 0, j + 24, k + 70, id);
		world.setBlock(i + 0, j + 24, k + 71, id);
		world.setBlock(i + 0, j + 24, k + 72, id);
		world.setBlock(i + 0, j + 24, k + 73, id);
		world.setBlock(i + 0, j + 24, k + 74, id);
		world.setBlock(i + 0, j + 24, k + 75, id);
		world.setBlock(i + 0, j + 24, k + 76, id);
		world.setBlock(i + 0, j + 24, k + 77, id);
		world.setBlock(i + 0, j + 24, k + 78, id);
		world.setBlock(i + 0, j + 24, k + 79, id);
		world.setBlock(i + 0, j + 25, k + 0, id);
		world.setBlock(i + 0, j + 25, k + 1, id);
		world.setBlock(i + 0, j + 25, k + 2, id);
		world.setBlock(i + 0, j + 25, k + 3, id);
		world.setBlock(i + 0, j + 25, k + 4, id);
		world.setBlock(i + 0, j + 25, k + 5, id);
		world.setBlock(i + 0, j + 25, k + 6, id);
		world.setBlock(i + 0, j + 25, k + 7, id);
		world.setBlock(i + 0, j + 25, k + 8, id);
		world.setBlock(i + 0, j + 25, k + 9, id);
		world.setBlock(i + 0, j + 25, k + 10, id);
		world.setBlock(i + 0, j + 25, k + 11, id);
		world.setBlock(i + 0, j + 25, k + 12, id);
		world.setBlock(i + 0, j + 25, k + 13, id);
		world.setBlock(i + 0, j + 25, k + 14, id);
		world.setBlock(i + 0, j + 25, k + 15, id);
		world.setBlock(i + 0, j + 25, k + 16, id);
		world.setBlock(i + 0, j + 25, k + 17, id);
		world.setBlock(i + 0, j + 25, k + 18, id);
		world.setBlock(i + 0, j + 25, k + 19, id);
		world.setBlock(i + 0, j + 25, k + 20, id);
		world.setBlock(i + 0, j + 25, k + 21, id);
		world.setBlock(i + 0, j + 25, k + 22, id);
		world.setBlock(i + 0, j + 25, k + 23, id);
		world.setBlock(i + 0, j + 25, k + 24, id);
		world.setBlock(i + 0, j + 25, k + 25, id);
		world.setBlock(i + 0, j + 25, k + 26, id);
		world.setBlock(i + 0, j + 25, k + 27, id);
		world.setBlock(i + 0, j + 25, k + 28, id);
		world.setBlock(i + 0, j + 25, k + 29, id);
		world.setBlock(i + 0, j + 25, k + 30, id);
		world.setBlock(i + 0, j + 25, k + 31, id);
		world.setBlock(i + 0, j + 25, k + 32, id);
		world.setBlock(i + 0, j + 25, k + 33, id);
		world.setBlock(i + 0, j + 25, k + 34, id);
		world.setBlock(i + 0, j + 25, k + 35, id);
		world.setBlock(i + 0, j + 25, k + 36, id);
		world.setBlock(i + 0, j + 25, k + 37, id);
		world.setBlock(i + 0, j + 25, k + 38, id);
		world.setBlock(i + 0, j + 25, k + 39, id);
		world.setBlock(i + 0, j + 25, k + 40, id);
		world.setBlock(i + 0, j + 25, k + 41, id);
		world.setBlock(i + 0, j + 25, k + 42, id);
		world.setBlock(i + 0, j + 25, k + 43, id);
		world.setBlock(i + 0, j + 25, k + 44, id);
		world.setBlock(i + 0, j + 25, k + 45, id);
		world.setBlock(i + 0, j + 25, k + 46, id);
		world.setBlock(i + 0, j + 25, k + 47, id);
		world.setBlock(i + 0, j + 25, k + 48, id);
		world.setBlock(i + 0, j + 25, k + 49, id);
		world.setBlock(i + 0, j + 25, k + 50, id);
		world.setBlock(i + 0, j + 25, k + 51, id);
		world.setBlock(i + 0, j + 25, k + 52, id);
		world.setBlock(i + 0, j + 25, k + 53, id);
		world.setBlock(i + 0, j + 25, k + 54, id);
		world.setBlock(i + 0, j + 25, k + 55, id);
		world.setBlock(i + 0, j + 25, k + 56, id);
		world.setBlock(i + 0, j + 25, k + 57, id);
		world.setBlock(i + 0, j + 25, k + 58, id);
		world.setBlock(i + 0, j + 25, k + 59, id);
		world.setBlock(i + 0, j + 25, k + 60, id);
		world.setBlock(i + 0, j + 25, k + 61, id);
		world.setBlock(i + 0, j + 25, k + 62, id);
		world.setBlock(i + 0, j + 25, k + 63, id);
		world.setBlock(i + 0, j + 25, k + 64, id);
		world.setBlock(i + 0, j + 25, k + 65, id);
		world.setBlock(i + 0, j + 25, k + 66, id);
		world.setBlock(i + 0, j + 25, k + 67, id);
		world.setBlock(i + 0, j + 25, k + 68, id);
		world.setBlock(i + 0, j + 25, k + 69, id);
		world.setBlock(i + 0, j + 25, k + 70, id);
		world.setBlock(i + 0, j + 25, k + 71, id);
		world.setBlock(i + 0, j + 25, k + 72, id);
		world.setBlock(i + 0, j + 25, k + 73, id);
		world.setBlock(i + 0, j + 25, k + 74, id);
		world.setBlock(i + 0, j + 25, k + 75, id);
		world.setBlock(i + 0, j + 25, k + 76, id);
		world.setBlock(i + 0, j + 25, k + 77, id);
		world.setBlock(i + 0, j + 25, k + 78, id);
		world.setBlock(i + 0, j + 25, k + 79, id);
		world.setBlock(i + 0, j + 30, k + 0, id);
		world.setBlock(i + 0, j + 30, k + 1, id);
		world.setBlock(i + 0, j + 30, k + 2, id);
		world.setBlock(i + 0, j + 30, k + 3, id);
		world.setBlock(i + 0, j + 30, k + 4, id);
		world.setBlock(i + 0, j + 30, k + 5, id);
		world.setBlock(i + 0, j + 30, k + 6, id);
		world.setBlock(i + 0, j + 30, k + 7, id);
		world.setBlock(i + 0, j + 30, k + 8, id);
		world.setBlock(i + 0, j + 30, k + 9, id);
		world.setBlock(i + 0, j + 30, k + 10, id);
		world.setBlock(i + 0, j + 30, k + 11, id);
		world.setBlock(i + 0, j + 30, k + 12, id);
		world.setBlock(i + 0, j + 30, k + 13, id);
		world.setBlock(i + 0, j + 30, k + 14, id);
		world.setBlock(i + 0, j + 30, k + 15, id);
		world.setBlock(i + 0, j + 30, k + 16, id);
		world.setBlock(i + 0, j + 30, k + 17, id);
		world.setBlock(i + 0, j + 30, k + 18, id);
		world.setBlock(i + 0, j + 30, k + 19, id);
		world.setBlock(i + 0, j + 30, k + 20, id);
		world.setBlock(i + 0, j + 30, k + 21, id);
		world.setBlock(i + 0, j + 30, k + 22, id);
		world.setBlock(i + 0, j + 30, k + 23, id);
		world.setBlock(i + 0, j + 30, k + 24, id);
		world.setBlock(i + 0, j + 30, k + 25, id);
		world.setBlock(i + 0, j + 30, k + 26, id);
		world.setBlock(i + 0, j + 30, k + 27, id);
		world.setBlock(i + 0, j + 30, k + 28, id);
		world.setBlock(i + 0, j + 30, k + 29, id);
		world.setBlock(i + 0, j + 30, k + 30, id);
		world.setBlock(i + 0, j + 30, k + 31, id);
		world.setBlock(i + 0, j + 30, k + 32, id);
		world.setBlock(i + 0, j + 30, k + 33, id);
		world.setBlock(i + 0, j + 30, k + 34, id);
		world.setBlock(i + 0, j + 30, k + 35, id);
		world.setBlock(i + 0, j + 30, k + 36, id);
		world.setBlock(i + 0, j + 30, k + 37, id);
		world.setBlock(i + 0, j + 30, k + 38, id);
		world.setBlock(i + 0, j + 30, k + 39, id);
		world.setBlock(i + 0, j + 30, k + 40, id);
		world.setBlock(i + 0, j + 30, k + 41, id);
		world.setBlock(i + 0, j + 30, k + 42, id);
		world.setBlock(i + 0, j + 30, k + 43, id);
		world.setBlock(i + 0, j + 30, k + 44, id);
		world.setBlock(i + 0, j + 30, k + 45, id);
		world.setBlock(i + 0, j + 30, k + 46, id);
		world.setBlock(i + 0, j + 30, k + 47, id);
		world.setBlock(i + 0, j + 30, k + 48, id);
		world.setBlock(i + 0, j + 30, k + 49, id);
		world.setBlock(i + 0, j + 30, k + 50, id);
		world.setBlock(i + 0, j + 30, k + 51, id);
		world.setBlock(i + 0, j + 30, k + 52, id);
		world.setBlock(i + 0, j + 30, k + 53, id);
		world.setBlock(i + 0, j + 30, k + 54, id);
		world.setBlock(i + 0, j + 30, k + 55, id);
		world.setBlock(i + 0, j + 30, k + 56, id);
		world.setBlock(i + 0, j + 30, k + 57, id);
		world.setBlock(i + 0, j + 30, k + 58, id);
		world.setBlock(i + 0, j + 30, k + 59, id);
		world.setBlock(i + 0, j + 30, k + 60, id);
		world.setBlock(i + 0, j + 30, k + 61, id);
		world.setBlock(i + 0, j + 30, k + 62, id);
		world.setBlock(i + 0, j + 30, k + 63, id);
		world.setBlock(i + 0, j + 30, k + 64, id);
		world.setBlock(i + 0, j + 30, k + 65, id);
		world.setBlock(i + 0, j + 30, k + 66, id);
		world.setBlock(i + 0, j + 30, k + 67, id);
		world.setBlock(i + 0, j + 30, k + 68, id);
		world.setBlock(i + 0, j + 30, k + 69, id);
		world.setBlock(i + 0, j + 30, k + 70, id);
		world.setBlock(i + 0, j + 30, k + 71, id);
		world.setBlock(i + 0, j + 30, k + 72, id);
		world.setBlock(i + 0, j + 30, k + 73, id);
		world.setBlock(i + 0, j + 30, k + 74, id);
		world.setBlock(i + 0, j + 30, k + 75, id);
		world.setBlock(i + 0, j + 30, k + 76, id);
		world.setBlock(i + 0, j + 30, k + 77, id);
		world.setBlock(i + 0, j + 30, k + 78, id);
		world.setBlock(i + 0, j + 30, k + 79, id);
		world.setBlock(i + 0, j + 31, k + 0, id);
		world.setBlock(i + 0, j + 31, k + 1, id);
		world.setBlock(i + 0, j + 31, k + 2, id);
		world.setBlock(i + 0, j + 31, k + 3, id);
		world.setBlock(i + 0, j + 31, k + 4, id);
		world.setBlock(i + 0, j + 31, k + 5, id);
		world.setBlock(i + 0, j + 31, k + 6, id);
		world.setBlock(i + 0, j + 31, k + 7, id);
		world.setBlock(i + 0, j + 31, k + 8, id);
		world.setBlock(i + 0, j + 31, k + 9, id);
		world.setBlock(i + 0, j + 31, k + 10, id);
		world.setBlock(i + 0, j + 31, k + 11, id);
		world.setBlock(i + 0, j + 31, k + 12, id);
		world.setBlock(i + 0, j + 31, k + 13, id);
		world.setBlock(i + 0, j + 31, k + 14, id);
		world.setBlock(i + 0, j + 31, k + 15, id);
		world.setBlock(i + 0, j + 31, k + 16, id);
		world.setBlock(i + 0, j + 31, k + 17, id);
		world.setBlock(i + 0, j + 31, k + 18, id);
		world.setBlock(i + 0, j + 31, k + 19, id);
		world.setBlock(i + 0, j + 31, k + 20, id);
		world.setBlock(i + 0, j + 31, k + 21, id);
		world.setBlock(i + 0, j + 31, k + 22, id);
		world.setBlock(i + 0, j + 31, k + 23, id);
		world.setBlock(i + 0, j + 31, k + 24, id);
		world.setBlock(i + 0, j + 31, k + 25, id);
		world.setBlock(i + 0, j + 31, k + 26, id);
		world.setBlock(i + 0, j + 31, k + 27, id);
		world.setBlock(i + 0, j + 31, k + 28, id);
		world.setBlock(i + 0, j + 31, k + 29, id);
		world.setBlock(i + 0, j + 31, k + 30, id);
		world.setBlock(i + 0, j + 31, k + 31, id);
		world.setBlock(i + 0, j + 31, k + 32, id);
		world.setBlock(i + 0, j + 31, k + 33, id);
		world.setBlock(i + 0, j + 31, k + 34, id);
		world.setBlock(i + 0, j + 31, k + 35, id);
		world.setBlock(i + 0, j + 31, k + 36, id);
		world.setBlock(i + 0, j + 31, k + 37, id);
		world.setBlock(i + 0, j + 31, k + 38, id);
		world.setBlock(i + 0, j + 31, k + 39, id);
		world.setBlock(i + 0, j + 31, k + 40, id);
		world.setBlock(i + 0, j + 31, k + 41, id);
		world.setBlock(i + 0, j + 31, k + 42, id);
		world.setBlock(i + 0, j + 31, k + 43, id);
		world.setBlock(i + 0, j + 31, k + 44, id);
		world.setBlock(i + 0, j + 31, k + 45, id);
		world.setBlock(i + 0, j + 31, k + 46, id);
		world.setBlock(i + 0, j + 31, k + 47, id);
		world.setBlock(i + 0, j + 31, k + 48, id);
		world.setBlock(i + 0, j + 31, k + 49, id);
		world.setBlock(i + 0, j + 31, k + 50, id);
		world.setBlock(i + 0, j + 31, k + 51, id);
		world.setBlock(i + 0, j + 31, k + 52, id);
		world.setBlock(i + 0, j + 31, k + 53, id);
		world.setBlock(i + 0, j + 31, k + 54, id);
		world.setBlock(i + 0, j + 31, k + 55, id);
		world.setBlock(i + 0, j + 31, k + 56, id);
		world.setBlock(i + 0, j + 31, k + 57, id);
		world.setBlock(i + 0, j + 31, k + 58, id);
		world.setBlock(i + 0, j + 31, k + 59, id);
		world.setBlock(i + 0, j + 31, k + 60, id);
		world.setBlock(i + 0, j + 31, k + 61, id);
		world.setBlock(i + 0, j + 31, k + 62, id);
		world.setBlock(i + 0, j + 31, k + 63, id);
		world.setBlock(i + 0, j + 31, k + 64, id);
		world.setBlock(i + 0, j + 31, k + 65, id);
		world.setBlock(i + 0, j + 31, k + 66, id);
		world.setBlock(i + 0, j + 31, k + 67, id);
		world.setBlock(i + 0, j + 31, k + 68, id);
		world.setBlock(i + 0, j + 31, k + 69, id);
		world.setBlock(i + 0, j + 31, k + 70, id);
		world.setBlock(i + 0, j + 31, k + 71, id);
		world.setBlock(i + 0, j + 31, k + 72, id);
		world.setBlock(i + 0, j + 31, k + 73, id);
		world.setBlock(i + 0, j + 31, k + 74, id);
		world.setBlock(i + 0, j + 31, k + 75, id);
		world.setBlock(i + 0, j + 31, k + 76, id);
		world.setBlock(i + 0, j + 31, k + 77, id);
		world.setBlock(i + 0, j + 31, k + 78, id);
		world.setBlock(i + 0, j + 31, k + 79, id);
		world.setBlock(i + 0, j + 32, k + 0, id);
		world.setBlock(i + 0, j + 32, k + 1, id);
		world.setBlock(i + 0, j + 32, k + 2, id);
		world.setBlock(i + 0, j + 32, k + 3, id);
		world.setBlock(i + 0, j + 32, k + 4, id);
		world.setBlock(i + 0, j + 32, k + 5, id);
		world.setBlock(i + 0, j + 32, k + 6, id);
		world.setBlock(i + 0, j + 32, k + 7, id);
		world.setBlock(i + 0, j + 32, k + 8, id);
		world.setBlock(i + 0, j + 32, k + 9, id);
		world.setBlock(i + 0, j + 32, k + 10, id);
		world.setBlock(i + 0, j + 32, k + 11, id);
		world.setBlock(i + 0, j + 32, k + 12, id);
		world.setBlock(i + 0, j + 32, k + 13, id);
		world.setBlock(i + 0, j + 32, k + 14, id);
		world.setBlock(i + 0, j + 32, k + 15, id);
		world.setBlock(i + 0, j + 32, k + 16, id);
		world.setBlock(i + 0, j + 32, k + 17, id);
		world.setBlock(i + 0, j + 32, k + 18, id);
		world.setBlock(i + 0, j + 32, k + 19, id);
		world.setBlock(i + 0, j + 32, k + 20, id);
		world.setBlock(i + 0, j + 32, k + 21, id);
		world.setBlock(i + 0, j + 32, k + 22, id);
		world.setBlock(i + 0, j + 32, k + 23, id);
		world.setBlock(i + 0, j + 32, k + 24, id);
		world.setBlock(i + 0, j + 32, k + 25, id);
		world.setBlock(i + 0, j + 32, k + 26, id);
		world.setBlock(i + 0, j + 32, k + 27, id);
		world.setBlock(i + 0, j + 32, k + 28, id);
		world.setBlock(i + 0, j + 32, k + 29, id);
		world.setBlock(i + 0, j + 32, k + 30, id);
		world.setBlock(i + 0, j + 32, k + 31, id);
		world.setBlock(i + 0, j + 32, k + 32, id);
		world.setBlock(i + 0, j + 32, k + 33, id);
		world.setBlock(i + 0, j + 32, k + 34, id);
		world.setBlock(i + 0, j + 32, k + 35, id);
		world.setBlock(i + 0, j + 32, k + 36, id);
		world.setBlock(i + 0, j + 32, k + 37, id);
		world.setBlock(i + 0, j + 32, k + 38, id);
		world.setBlock(i + 0, j + 32, k + 39, id);
		world.setBlock(i + 0, j + 32, k + 40, id);
		world.setBlock(i + 0, j + 32, k + 41, id);
		world.setBlock(i + 0, j + 32, k + 42, id);
		world.setBlock(i + 0, j + 32, k + 43, id);
		world.setBlock(i + 0, j + 32, k + 44, id);
		world.setBlock(i + 0, j + 32, k + 45, id);
		world.setBlock(i + 0, j + 32, k + 46, id);
		world.setBlock(i + 0, j + 32, k + 47, id);
		world.setBlock(i + 0, j + 32, k + 48, id);
		world.setBlock(i + 0, j + 32, k + 49, id);
		world.setBlock(i + 0, j + 32, k + 50, id);
		world.setBlock(i + 0, j + 32, k + 51, id);
		world.setBlock(i + 0, j + 32, k + 52, id);
		world.setBlock(i + 0, j + 32, k + 53, id);
		world.setBlock(i + 0, j + 32, k + 54, id);
		world.setBlock(i + 0, j + 32, k + 55, id);
		world.setBlock(i + 0, j + 32, k + 56, id);
		world.setBlock(i + 0, j + 32, k + 57, id);
		world.setBlock(i + 0, j + 32, k + 58, id);
		world.setBlock(i + 0, j + 32, k + 59, id);
		world.setBlock(i + 0, j + 32, k + 60, id);
		world.setBlock(i + 0, j + 32, k + 61, id);
		world.setBlock(i + 0, j + 32, k + 62, id);
		world.setBlock(i + 0, j + 32, k + 63, id);
		world.setBlock(i + 0, j + 32, k + 64, id);
		world.setBlock(i + 0, j + 32, k + 65, id);
		world.setBlock(i + 0, j + 32, k + 66, id);
		world.setBlock(i + 0, j + 32, k + 67, id);
		world.setBlock(i + 0, j + 32, k + 68, id);
		world.setBlock(i + 0, j + 32, k + 69, id);
		world.setBlock(i + 0, j + 32, k + 70, id);
		world.setBlock(i + 0, j + 32, k + 71, id);
		world.setBlock(i + 0, j + 32, k + 72, id);
		world.setBlock(i + 0, j + 32, k + 73, id);
		world.setBlock(i + 0, j + 32, k + 74, id);
		world.setBlock(i + 0, j + 32, k + 75, id);
		world.setBlock(i + 0, j + 32, k + 76, id);
		world.setBlock(i + 0, j + 32, k + 77, id);
		world.setBlock(i + 0, j + 32, k + 78, id);
		world.setBlock(i + 0, j + 32, k + 79, id);
		world.setBlock(i + 0, j + 33, k + 0, id);
		world.setBlock(i + 0, j + 33, k + 1, id);
		world.setBlock(i + 0, j + 33, k + 2, id);
		world.setBlock(i + 0, j + 33, k + 3, id);
		world.setBlock(i + 0, j + 33, k + 4, id);
		world.setBlock(i + 0, j + 33, k + 5, id);
		world.setBlock(i + 0, j + 33, k + 6, id);
		world.setBlock(i + 0, j + 33, k + 7, id);
		world.setBlock(i + 0, j + 33, k + 8, id);
		world.setBlock(i + 0, j + 33, k + 9, id);
		world.setBlock(i + 0, j + 33, k + 10, id);
		world.setBlock(i + 0, j + 33, k + 11, id);
		world.setBlock(i + 0, j + 33, k + 12, id);
		world.setBlock(i + 0, j + 33, k + 13, id);
		world.setBlock(i + 0, j + 33, k + 14, id);
		world.setBlock(i + 0, j + 33, k + 15, id);
		world.setBlock(i + 0, j + 33, k + 16, id);
		world.setBlock(i + 0, j + 33, k + 17, id);
		world.setBlock(i + 0, j + 33, k + 18, id);
		world.setBlock(i + 0, j + 33, k + 19, id);
		world.setBlock(i + 0, j + 33, k + 20, id);
		world.setBlock(i + 0, j + 33, k + 21, id);
		world.setBlock(i + 0, j + 33, k + 22, id);
		world.setBlock(i + 0, j + 33, k + 23, id);
		world.setBlock(i + 0, j + 33, k + 24, id);
		world.setBlock(i + 0, j + 33, k + 25, id);
		world.setBlock(i + 0, j + 33, k + 26, id);
		world.setBlock(i + 0, j + 33, k + 27, id);
		world.setBlock(i + 0, j + 33, k + 28, id);
		world.setBlock(i + 0, j + 33, k + 29, id);
		world.setBlock(i + 0, j + 33, k + 30, id);
		world.setBlock(i + 0, j + 33, k + 31, id);
		world.setBlock(i + 0, j + 33, k + 32, id);
		world.setBlock(i + 0, j + 33, k + 33, id);
		world.setBlock(i + 0, j + 33, k + 34, id);
		world.setBlock(i + 0, j + 33, k + 35, id);
		world.setBlock(i + 0, j + 33, k + 36, id);
		world.setBlock(i + 0, j + 33, k + 37, id);
		world.setBlock(i + 0, j + 33, k + 38, id);
		world.setBlock(i + 0, j + 33, k + 39, id);
		world.setBlock(i + 0, j + 33, k + 40, id);
		world.setBlock(i + 0, j + 33, k + 41, id);
		world.setBlock(i + 0, j + 33, k + 42, id);
		world.setBlock(i + 0, j + 33, k + 43, id);
		world.setBlock(i + 0, j + 33, k + 44, id);
		world.setBlock(i + 0, j + 33, k + 45, id);
		world.setBlock(i + 0, j + 33, k + 46, id);
		world.setBlock(i + 0, j + 33, k + 47, id);
		world.setBlock(i + 0, j + 33, k + 48, id);
		world.setBlock(i + 0, j + 33, k + 49, id);
		world.setBlock(i + 0, j + 33, k + 50, id);
		world.setBlock(i + 0, j + 33, k + 51, id);
		world.setBlock(i + 0, j + 33, k + 52, id);
		world.setBlock(i + 0, j + 33, k + 53, id);
		world.setBlock(i + 0, j + 33, k + 54, id);
		world.setBlock(i + 0, j + 33, k + 55, id);
		world.setBlock(i + 0, j + 33, k + 56, id);
		world.setBlock(i + 0, j + 33, k + 57, id);
		world.setBlock(i + 0, j + 33, k + 58, id);
		world.setBlock(i + 0, j + 33, k + 59, id);
		world.setBlock(i + 0, j + 33, k + 60, id);
		world.setBlock(i + 0, j + 33, k + 61, id);
		world.setBlock(i + 0, j + 33, k + 62, id);
		world.setBlock(i + 0, j + 33, k + 63, id);
		world.setBlock(i + 0, j + 33, k + 64, id);
		world.setBlock(i + 0, j + 33, k + 65, id);
		world.setBlock(i + 0, j + 33, k + 66, id);
		world.setBlock(i + 0, j + 33, k + 67, id);
		world.setBlock(i + 0, j + 33, k + 68, id);
		world.setBlock(i + 0, j + 33, k + 69, id);
		world.setBlock(i + 0, j + 33, k + 70, id);
		world.setBlock(i + 0, j + 33, k + 71, id);
		world.setBlock(i + 0, j + 33, k + 72, id);
		world.setBlock(i + 0, j + 33, k + 73, id);
		world.setBlock(i + 0, j + 33, k + 74, id);
		world.setBlock(i + 0, j + 33, k + 75, id);
		world.setBlock(i + 0, j + 33, k + 76, id);
		world.setBlock(i + 0, j + 33, k + 77, id);
		world.setBlock(i + 0, j + 33, k + 78, id);
		world.setBlock(i + 0, j + 33, k + 79, id);
		world.setBlock(i + 0, j + 34, k + 0, id);
		world.setBlock(i + 0, j + 34, k + 1, id);
		world.setBlock(i + 0, j + 34, k + 2, id);
		world.setBlock(i + 0, j + 34, k + 3, id);
		world.setBlock(i + 0, j + 34, k + 4, id);
		world.setBlock(i + 0, j + 34, k + 5, id);
		world.setBlock(i + 0, j + 34, k + 6, id);
		world.setBlock(i + 0, j + 34, k + 7, id);
		world.setBlock(i + 0, j + 34, k + 8, id);
		world.setBlock(i + 0, j + 34, k + 9, id);
		world.setBlock(i + 0, j + 34, k + 10, id);
		world.setBlock(i + 0, j + 34, k + 11, id);
		world.setBlock(i + 0, j + 34, k + 12, id);
		world.setBlock(i + 0, j + 34, k + 13, id);
		world.setBlock(i + 0, j + 34, k + 14, id);
		world.setBlock(i + 0, j + 34, k + 15, id);
		world.setBlock(i + 0, j + 34, k + 16, id);
		world.setBlock(i + 0, j + 34, k + 17, id);
		world.setBlock(i + 0, j + 34, k + 18, id);
		world.setBlock(i + 0, j + 34, k + 19, id);
		world.setBlock(i + 0, j + 34, k + 20, id);
		world.setBlock(i + 0, j + 34, k + 21, id);
		world.setBlock(i + 0, j + 34, k + 22, id);
		world.setBlock(i + 0, j + 34, k + 23, id);
		world.setBlock(i + 0, j + 34, k + 24, id);
		world.setBlock(i + 0, j + 34, k + 25, id);
		world.setBlock(i + 0, j + 34, k + 26, id);
		world.setBlock(i + 0, j + 34, k + 27, id);
		world.setBlock(i + 0, j + 34, k + 28, id);
		world.setBlock(i + 0, j + 34, k + 29, id);
		world.setBlock(i + 0, j + 34, k + 30, id);
		world.setBlock(i + 0, j + 34, k + 31, id);
		world.setBlock(i + 0, j + 34, k + 32, id);
		world.setBlock(i + 0, j + 34, k + 33, id);
		world.setBlock(i + 0, j + 34, k + 34, id);
		world.setBlock(i + 0, j + 34, k + 35, id);
		world.setBlock(i + 0, j + 34, k + 36, id);
		world.setBlock(i + 0, j + 34, k + 37, id);
		world.setBlock(i + 0, j + 34, k + 38, id);
		world.setBlock(i + 0, j + 34, k + 39, id);
		world.setBlock(i + 0, j + 34, k + 40, id);
		world.setBlock(i + 0, j + 34, k + 41, id);
		world.setBlock(i + 0, j + 34, k + 42, id);
		world.setBlock(i + 0, j + 34, k + 43, id);
		world.setBlock(i + 0, j + 34, k + 44, id);
		world.setBlock(i + 0, j + 34, k + 45, id);
		world.setBlock(i + 0, j + 34, k + 46, id);
		world.setBlock(i + 0, j + 34, k + 47, id);
		world.setBlock(i + 0, j + 34, k + 48, id);
		world.setBlock(i + 0, j + 34, k + 49, id);
		world.setBlock(i + 0, j + 34, k + 50, id);
		world.setBlock(i + 0, j + 34, k + 51, id);
		world.setBlock(i + 0, j + 34, k + 52, id);
		world.setBlock(i + 0, j + 34, k + 53, id);
		world.setBlock(i + 0, j + 34, k + 54, id);
		world.setBlock(i + 0, j + 34, k + 55, id);
		world.setBlock(i + 0, j + 34, k + 56, id);
		world.setBlock(i + 0, j + 34, k + 57, id);
		world.setBlock(i + 0, j + 34, k + 58, id);
		world.setBlock(i + 0, j + 34, k + 59, id);
		world.setBlock(i + 0, j + 34, k + 60, id);
		world.setBlock(i + 0, j + 34, k + 61, id);
		world.setBlock(i + 0, j + 34, k + 62, id);
		world.setBlock(i + 0, j + 34, k + 63, id);
		world.setBlock(i + 0, j + 34, k + 64, id);
		world.setBlock(i + 0, j + 34, k + 65, id);
		world.setBlock(i + 0, j + 34, k + 66, id);
		world.setBlock(i + 0, j + 34, k + 67, id);
		world.setBlock(i + 0, j + 34, k + 68, id);
		world.setBlock(i + 0, j + 34, k + 69, id);
		world.setBlock(i + 0, j + 34, k + 70, id);
		world.setBlock(i + 0, j + 34, k + 71, id);
		world.setBlock(i + 0, j + 34, k + 72, id);
		world.setBlock(i + 0, j + 34, k + 73, id);
		world.setBlock(i + 0, j + 34, k + 74, id);
		world.setBlock(i + 0, j + 34, k + 75, id);
		world.setBlock(i + 0, j + 34, k + 76, id);
		world.setBlock(i + 0, j + 34, k + 77, id);
		world.setBlock(i + 0, j + 34, k + 78, id);
		world.setBlock(i + 0, j + 34, k + 79, id);
		world.setBlock(i + 0, j + 35, k + 0, id);
		world.setBlock(i + 0, j + 35, k + 1, id);
		world.setBlock(i + 0, j + 35, k + 2, id);
		world.setBlock(i + 0, j + 35, k + 3, id);
		world.setBlock(i + 0, j + 35, k + 4, id);
		world.setBlock(i + 0, j + 35, k + 5, id);
		world.setBlock(i + 0, j + 35, k + 6, id);
		world.setBlock(i + 0, j + 35, k + 7, id);
		world.setBlock(i + 0, j + 35, k + 8, id);
		world.setBlock(i + 0, j + 35, k + 9, id);
		world.setBlock(i + 0, j + 35, k + 10, id);
		world.setBlock(i + 0, j + 35, k + 11, id);
		world.setBlock(i + 0, j + 35, k + 12, id);
		world.setBlock(i + 0, j + 35, k + 13, id);
		world.setBlock(i + 0, j + 35, k + 14, id);
		world.setBlock(i + 0, j + 35, k + 15, id);
		world.setBlock(i + 0, j + 35, k + 16, id);
		world.setBlock(i + 0, j + 35, k + 17, id);
		world.setBlock(i + 0, j + 35, k + 18, id);
		world.setBlock(i + 0, j + 35, k + 19, id);
		world.setBlock(i + 0, j + 35, k + 20, id);
		world.setBlock(i + 0, j + 35, k + 21, id);
		world.setBlock(i + 0, j + 35, k + 22, id);
		world.setBlock(i + 0, j + 35, k + 23, id);
		world.setBlock(i + 0, j + 35, k + 24, id);
		world.setBlock(i + 0, j + 35, k + 25, id);
		world.setBlock(i + 0, j + 35, k + 26, id);
		world.setBlock(i + 0, j + 35, k + 27, id);
		world.setBlock(i + 0, j + 35, k + 28, id);
		world.setBlock(i + 0, j + 35, k + 29, id);
		world.setBlock(i + 0, j + 35, k + 30, id);
		world.setBlock(i + 0, j + 35, k + 31, id);
		world.setBlock(i + 0, j + 35, k + 32, id);
		world.setBlock(i + 0, j + 35, k + 33, id);
		world.setBlock(i + 0, j + 35, k + 34, id);
		world.setBlock(i + 0, j + 35, k + 35, id);
		world.setBlock(i + 0, j + 35, k + 36, id);
		world.setBlock(i + 0, j + 35, k + 37, id);
		world.setBlock(i + 0, j + 35, k + 38, id);
		world.setBlock(i + 0, j + 35, k + 39, id);
		world.setBlock(i + 0, j + 35, k + 40, id);
		world.setBlock(i + 0, j + 35, k + 41, id);
		world.setBlock(i + 0, j + 35, k + 42, id);
		world.setBlock(i + 0, j + 35, k + 43, id);
		world.setBlock(i + 0, j + 35, k + 44, id);
		world.setBlock(i + 0, j + 35, k + 45, id);
		world.setBlock(i + 0, j + 35, k + 46, id);
		world.setBlock(i + 0, j + 35, k + 47, id);
		world.setBlock(i + 0, j + 35, k + 48, id);
		world.setBlock(i + 0, j + 35, k + 49, id);
		world.setBlock(i + 0, j + 35, k + 50, id);
		world.setBlock(i + 0, j + 35, k + 51, id);
		world.setBlock(i + 0, j + 35, k + 52, id);
		world.setBlock(i + 0, j + 35, k + 53, id);
		world.setBlock(i + 0, j + 35, k + 54, id);
		world.setBlock(i + 0, j + 35, k + 55, id);
		world.setBlock(i + 0, j + 35, k + 56, id);
		world.setBlock(i + 0, j + 35, k + 57, id);
		world.setBlock(i + 0, j + 35, k + 58, id);
		world.setBlock(i + 0, j + 35, k + 59, id);
		world.setBlock(i + 0, j + 35, k + 60, id);
		world.setBlock(i + 0, j + 35, k + 61, id);
		world.setBlock(i + 0, j + 35, k + 62, id);
		world.setBlock(i + 0, j + 35, k + 63, id);
		world.setBlock(i + 0, j + 35, k + 64, id);
		world.setBlock(i + 0, j + 35, k + 65, id);
		world.setBlock(i + 0, j + 35, k + 66, id);
		world.setBlock(i + 0, j + 35, k + 67, id);
		world.setBlock(i + 0, j + 35, k + 68, id);
		world.setBlock(i + 0, j + 35, k + 69, id);
		world.setBlock(i + 0, j + 35, k + 70, id);
		world.setBlock(i + 0, j + 35, k + 71, id);
		world.setBlock(i + 0, j + 35, k + 72, id);
		world.setBlock(i + 0, j + 35, k + 73, id);
		world.setBlock(i + 0, j + 35, k + 74, id);
		world.setBlock(i + 0, j + 35, k + 75, id);
		world.setBlock(i + 0, j + 35, k + 76, id);
		world.setBlock(i + 0, j + 35, k + 77, id);
		world.setBlock(i + 0, j + 35, k + 78, id);
		world.setBlock(i + 0, j + 35, k + 79, id);
		world.setBlock(i + 0, j + 36, k + 0, id);
		world.setBlock(i + 0, j + 36, k + 1, id);
		world.setBlock(i + 0, j + 36, k + 2, id);
		world.setBlock(i + 0, j + 36, k + 3, id);
		world.setBlock(i + 0, j + 36, k + 4, id);
		world.setBlock(i + 0, j + 36, k + 5, id);
		world.setBlock(i + 0, j + 36, k + 6, id);
		world.setBlock(i + 0, j + 36, k + 7, id);
		world.setBlock(i + 0, j + 36, k + 8, id);
		world.setBlock(i + 0, j + 36, k + 9, id);
		world.setBlock(i + 0, j + 36, k + 10, id);
		world.setBlock(i + 0, j + 36, k + 11, id);
		world.setBlock(i + 0, j + 36, k + 12, id);
		world.setBlock(i + 0, j + 36, k + 13, id);
		world.setBlock(i + 0, j + 36, k + 14, id);
		world.setBlock(i + 0, j + 36, k + 15, id);
		world.setBlock(i + 0, j + 36, k + 16, id);
		world.setBlock(i + 0, j + 36, k + 17, id);
		world.setBlock(i + 0, j + 36, k + 18, id);
		world.setBlock(i + 0, j + 36, k + 19, id);
		world.setBlock(i + 0, j + 36, k + 20, id);
		world.setBlock(i + 0, j + 36, k + 21, id);
		world.setBlock(i + 0, j + 36, k + 22, id);
		world.setBlock(i + 0, j + 36, k + 23, id);
		world.setBlock(i + 0, j + 36, k + 24, id);
		world.setBlock(i + 0, j + 36, k + 25, id);
		world.setBlock(i + 0, j + 36, k + 26, id);
		world.setBlock(i + 0, j + 36, k + 27, id);
		world.setBlock(i + 0, j + 36, k + 28, id);
		world.setBlock(i + 0, j + 36, k + 29, id);
		world.setBlock(i + 0, j + 36, k + 30, id);
		world.setBlock(i + 0, j + 36, k + 31, id);
		world.setBlock(i + 0, j + 36, k + 32, id);
		world.setBlock(i + 0, j + 36, k + 33, id);
		world.setBlock(i + 0, j + 36, k + 34, id);
		world.setBlock(i + 0, j + 36, k + 35, id);
		world.setBlock(i + 0, j + 36, k + 36, id);
		world.setBlock(i + 0, j + 36, k + 37, id);
		world.setBlock(i + 0, j + 36, k + 38, id);
		world.setBlock(i + 0, j + 36, k + 39, id);
		world.setBlock(i + 0, j + 36, k + 40, id);
		world.setBlock(i + 0, j + 36, k + 41, id);
		world.setBlock(i + 0, j + 36, k + 42, id);
		world.setBlock(i + 0, j + 36, k + 43, id);
		world.setBlock(i + 0, j + 36, k + 44, id);
		world.setBlock(i + 0, j + 36, k + 45, id);
		world.setBlock(i + 0, j + 36, k + 46, id);
		world.setBlock(i + 0, j + 36, k + 47, id);
		world.setBlock(i + 0, j + 36, k + 48, id);
		world.setBlock(i + 0, j + 36, k + 49, id);
		world.setBlock(i + 0, j + 36, k + 50, id);
		world.setBlock(i + 0, j + 36, k + 51, id);
		world.setBlock(i + 0, j + 36, k + 52, id);
		world.setBlock(i + 0, j + 36, k + 53, id);
		world.setBlock(i + 0, j + 36, k + 54, id);
		world.setBlock(i + 0, j + 36, k + 55, id);
		world.setBlock(i + 0, j + 36, k + 56, id);
		world.setBlock(i + 0, j + 36, k + 57, id);
		world.setBlock(i + 0, j + 36, k + 58, id);
		world.setBlock(i + 0, j + 36, k + 59, id);
		world.setBlock(i + 0, j + 36, k + 60, id);
		world.setBlock(i + 0, j + 36, k + 61, id);
		world.setBlock(i + 0, j + 36, k + 62, id);
		world.setBlock(i + 0, j + 36, k + 63, id);
		world.setBlock(i + 0, j + 36, k + 64, id);
		world.setBlock(i + 0, j + 36, k + 65, id);
		world.setBlock(i + 0, j + 36, k + 66, id);
		world.setBlock(i + 0, j + 36, k + 67, id);
		world.setBlock(i + 0, j + 36, k + 68, id);
		world.setBlock(i + 0, j + 36, k + 69, id);
		world.setBlock(i + 0, j + 36, k + 70, id);
		world.setBlock(i + 0, j + 36, k + 71, id);
		world.setBlock(i + 0, j + 36, k + 72, id);
		world.setBlock(i + 0, j + 36, k + 73, id);
		world.setBlock(i + 0, j + 36, k + 74, id);
		world.setBlock(i + 0, j + 36, k + 75, id);
		world.setBlock(i + 0, j + 36, k + 76, id);
		world.setBlock(i + 0, j + 36, k + 77, id);
		world.setBlock(i + 0, j + 36, k + 78, id);
		world.setBlock(i + 0, j + 36, k + 79, id);
		world.setBlock(i + 1, j + 19, k + 0, id);
		world.setBlock(i + 1, j + 19, k + 1, id);
		world.setBlock(i + 1, j + 19, k + 2, id);
		world.setBlock(i + 1, j + 19, k + 3, id);
		world.setBlock(i + 1, j + 19, k + 4, id);
		world.setBlock(i + 1, j + 19, k + 5, id);
		world.setBlock(i + 1, j + 19, k + 6, id);
		world.setBlock(i + 1, j + 19, k + 7, id);
		world.setBlock(i + 1, j + 19, k + 8, id);
		world.setBlock(i + 1, j + 19, k + 9, id);
		world.setBlock(i + 1, j + 19, k + 10, id);
		world.setBlock(i + 1, j + 19, k + 11, id);
		world.setBlock(i + 1, j + 19, k + 12, id);
		world.setBlock(i + 1, j + 19, k + 13, id);
		world.setBlock(i + 1, j + 19, k + 14, id);
		world.setBlock(i + 1, j + 19, k + 15, id);
		world.setBlock(i + 1, j + 19, k + 16, id);
		world.setBlock(i + 1, j + 19, k + 17, id);
		world.setBlock(i + 1, j + 19, k + 18, id);
		world.setBlock(i + 1, j + 19, k + 19, id);
		world.setBlock(i + 1, j + 19, k + 20, id);
		world.setBlock(i + 1, j + 19, k + 21, id);
		world.setBlock(i + 1, j + 19, k + 22, id);
		world.setBlock(i + 1, j + 19, k + 23, id);
		world.setBlock(i + 1, j + 19, k + 24, id);
		world.setBlock(i + 1, j + 19, k + 25, id);
		world.setBlock(i + 1, j + 19, k + 26, id);
		world.setBlock(i + 1, j + 19, k + 27, id);
		world.setBlock(i + 1, j + 19, k + 28, id);
		world.setBlock(i + 1, j + 19, k + 29, id);
		world.setBlock(i + 1, j + 19, k + 30, id);
		world.setBlock(i + 1, j + 19, k + 31, id);
		world.setBlock(i + 1, j + 19, k + 32, id);
		world.setBlock(i + 1, j + 19, k + 33, id);
		world.setBlock(i + 1, j + 19, k + 34, id);
		world.setBlock(i + 1, j + 19, k + 35, id);
		world.setBlock(i + 1, j + 19, k + 36, id);
		world.setBlock(i + 1, j + 19, k + 37, id);
		world.setBlock(i + 1, j + 19, k + 38, id);
		world.setBlock(i + 1, j + 19, k + 39, id);
		world.setBlock(i + 1, j + 19, k + 40, id);
		world.setBlock(i + 1, j + 19, k + 41, id);
		world.setBlock(i + 1, j + 19, k + 42, id);
		world.setBlock(i + 1, j + 19, k + 43, id);
		world.setBlock(i + 1, j + 19, k + 44, id);
		world.setBlock(i + 1, j + 19, k + 45, id);
		world.setBlock(i + 1, j + 19, k + 46, id);
		world.setBlock(i + 1, j + 19, k + 47, id);
		world.setBlock(i + 1, j + 19, k + 48, id);
		world.setBlock(i + 1, j + 19, k + 49, id);
		world.setBlock(i + 1, j + 19, k + 50, id);
		world.setBlock(i + 1, j + 19, k + 51, id);
		world.setBlock(i + 1, j + 19, k + 52, id);
		world.setBlock(i + 1, j + 19, k + 53, id);
		world.setBlock(i + 1, j + 19, k + 54, id);
		world.setBlock(i + 1, j + 19, k + 55, id);
		world.setBlock(i + 1, j + 19, k + 56, id);
		world.setBlock(i + 1, j + 19, k + 57, id);
		world.setBlock(i + 1, j + 19, k + 58, id);
		world.setBlock(i + 1, j + 19, k + 59, id);
		world.setBlock(i + 1, j + 19, k + 60, id);
		world.setBlock(i + 1, j + 19, k + 61, id);
		world.setBlock(i + 1, j + 19, k + 62, id);
		world.setBlock(i + 1, j + 19, k + 63, id);
		world.setBlock(i + 1, j + 19, k + 64, id);
		world.setBlock(i + 1, j + 19, k + 65, id);
		world.setBlock(i + 1, j + 19, k + 66, id);
		world.setBlock(i + 1, j + 19, k + 67, id);
		world.setBlock(i + 1, j + 19, k + 68, id);
		world.setBlock(i + 1, j + 19, k + 69, id);
		world.setBlock(i + 1, j + 19, k + 70, id);
		world.setBlock(i + 1, j + 19, k + 71, id);
		world.setBlock(i + 1, j + 19, k + 72, id);
		world.setBlock(i + 1, j + 19, k + 73, id);
		world.setBlock(i + 1, j + 19, k + 74, id);
		world.setBlock(i + 1, j + 19, k + 75, id);
		world.setBlock(i + 1, j + 19, k + 76, id);
		world.setBlock(i + 1, j + 19, k + 77, id);
		world.setBlock(i + 1, j + 19, k + 78, id);
		world.setBlock(i + 1, j + 19, k + 79, id);
		world.setBlock(i + 1, j + 20, k + 0, id);
		world.setBlock(i + 1, j + 20, k + 79, id);
		world.setBlock(i + 1, j + 21, k + 0, id);
		world.setBlock(i + 1, j + 21, k + 79, id);
		world.setBlock(i + 1, j + 22, k + 0, id);
		world.setBlock(i + 1, j + 22, k + 79, id);
		world.setBlock(i + 1, j + 23, k + 0, id);
		world.setBlock(i + 1, j + 23, k + 79, id);
		world.setBlock(i + 1, j + 24, k + 0, id);
		world.setBlock(i + 1, j + 24, k + 79, id);
		world.setBlock(i + 1, j + 25, k + 0, id);
		world.setBlock(i + 1, j + 25, k + 1, id);
		world.setBlock(i + 1, j + 25, k + 2, id);
		world.setBlock(i + 1, j + 25, k + 3, id);
		world.setBlock(i + 1, j + 25, k + 4, id);
		world.setBlock(i + 1, j + 25, k + 5, id);
		world.setBlock(i + 1, j + 25, k + 6, id);
		world.setBlock(i + 1, j + 25, k + 7, id);
		world.setBlock(i + 1, j + 25, k + 8, id);
		world.setBlock(i + 1, j + 25, k + 9, id);
		world.setBlock(i + 1, j + 25, k + 10, id);
		world.setBlock(i + 1, j + 25, k + 11, id);
		world.setBlock(i + 1, j + 25, k + 12, id);
		world.setBlock(i + 1, j + 25, k + 13, id);
		world.setBlock(i + 1, j + 25, k + 14, id);
		world.setBlock(i + 1, j + 25, k + 15, id);
		world.setBlock(i + 1, j + 25, k + 16, id);
		world.setBlock(i + 1, j + 25, k + 17, id);
		world.setBlock(i + 1, j + 25, k + 18, id);
		world.setBlock(i + 1, j + 25, k + 19, id);
		world.setBlock(i + 1, j + 25, k + 20, id);
		world.setBlock(i + 1, j + 25, k + 21, id);
		world.setBlock(i + 1, j + 25, k + 22, id);
		world.setBlock(i + 1, j + 25, k + 23, id);
		world.setBlock(i + 1, j + 25, k + 24, id);
		world.setBlock(i + 1, j + 25, k + 25, id);
		world.setBlock(i + 1, j + 25, k + 26, id);
		world.setBlock(i + 1, j + 25, k + 27, id);
		world.setBlock(i + 1, j + 25, k + 28, id);
		world.setBlock(i + 1, j + 25, k + 29, id);
		world.setBlock(i + 1, j + 25, k + 30, id);
		world.setBlock(i + 1, j + 25, k + 31, id);
		world.setBlock(i + 1, j + 25, k + 32, id);
		world.setBlock(i + 1, j + 25, k + 33, id);
		world.setBlock(i + 1, j + 25, k + 34, id);
		world.setBlock(i + 1, j + 25, k + 35, id);
		world.setBlock(i + 1, j + 25, k + 36, id);
		world.setBlock(i + 1, j + 25, k + 37, id);
		world.setBlock(i + 1, j + 25, k + 38, id);
		world.setBlock(i + 1, j + 25, k + 39, id);
		world.setBlock(i + 1, j + 25, k + 40, id);
		world.setBlock(i + 1, j + 25, k + 41, id);
		world.setBlock(i + 1, j + 25, k + 42, id);
		world.setBlock(i + 1, j + 25, k + 43, id);
		world.setBlock(i + 1, j + 25, k + 44, id);
		world.setBlock(i + 1, j + 25, k + 45, id);
		world.setBlock(i + 1, j + 25, k + 46, id);
		world.setBlock(i + 1, j + 25, k + 47, id);
		world.setBlock(i + 1, j + 25, k + 48, id);
		world.setBlock(i + 1, j + 25, k + 49, id);
		world.setBlock(i + 1, j + 25, k + 50, id);
		world.setBlock(i + 1, j + 25, k + 51, id);
		world.setBlock(i + 1, j + 25, k + 52, id);
		world.setBlock(i + 1, j + 25, k + 53, id);
		world.setBlock(i + 1, j + 25, k + 54, id);
		world.setBlock(i + 1, j + 25, k + 55, id);
		world.setBlock(i + 1, j + 25, k + 56, id);
		world.setBlock(i + 1, j + 25, k + 57, id);
		world.setBlock(i + 1, j + 25, k + 58, id);
		world.setBlock(i + 1, j + 25, k + 59, id);
		world.setBlock(i + 1, j + 25, k + 60, id);
		world.setBlock(i + 1, j + 25, k + 61, id);
		world.setBlock(i + 1, j + 25, k + 62, id);
		world.setBlock(i + 1, j + 25, k + 63, id);
		world.setBlock(i + 1, j + 25, k + 64, id);
		world.setBlock(i + 1, j + 25, k + 65, id);
		world.setBlock(i + 1, j + 25, k + 66, id);
		world.setBlock(i + 1, j + 25, k + 67, id);
		world.setBlock(i + 1, j + 25, k + 68, id);
		world.setBlock(i + 1, j + 25, k + 69, id);
		world.setBlock(i + 1, j + 25, k + 70, id);
		world.setBlock(i + 1, j + 25, k + 71, id);
		world.setBlock(i + 1, j + 25, k + 72, id);
		world.setBlock(i + 1, j + 25, k + 73, id);
		world.setBlock(i + 1, j + 25, k + 74, id);
		world.setBlock(i + 1, j + 25, k + 75, id);
		world.setBlock(i + 1, j + 25, k + 76, id);
		world.setBlock(i + 1, j + 25, k + 77, id);
		world.setBlock(i + 1, j + 25, k + 78, id);
		world.setBlock(i + 1, j + 25, k + 79, id);
		world.setBlock(i + 1, j + 30, k + 0, id);
		world.setBlock(i + 1, j + 30, k + 1, id);
		world.setBlock(i + 1, j + 30, k + 2, id);
		world.setBlock(i + 1, j + 30, k + 3, id);
		world.setBlock(i + 1, j + 30, k + 4, id);
		world.setBlock(i + 1, j + 30, k + 5, id);
		world.setBlock(i + 1, j + 30, k + 6, id);
		world.setBlock(i + 1, j + 30, k + 7, id);
		world.setBlock(i + 1, j + 30, k + 8, id);
		world.setBlock(i + 1, j + 30, k + 9, id);
		world.setBlock(i + 1, j + 30, k + 10, id);
		world.setBlock(i + 1, j + 30, k + 11, id);
		world.setBlock(i + 1, j + 30, k + 12, id);
		world.setBlock(i + 1, j + 30, k + 13, id);
		world.setBlock(i + 1, j + 30, k + 14, id);
		world.setBlock(i + 1, j + 30, k + 15, id);
		world.setBlock(i + 1, j + 30, k + 16, id);
		world.setBlock(i + 1, j + 30, k + 17, id);
		world.setBlock(i + 1, j + 30, k + 18, id);
		world.setBlock(i + 1, j + 30, k + 19, id);
		world.setBlock(i + 1, j + 30, k + 20, id);
		world.setBlock(i + 1, j + 30, k + 21, id);
		world.setBlock(i + 1, j + 30, k + 22, id);
		world.setBlock(i + 1, j + 30, k + 23, id);
		world.setBlock(i + 1, j + 30, k + 24, id);
		world.setBlock(i + 1, j + 30, k + 25, id);
		world.setBlock(i + 1, j + 30, k + 26, id);
		world.setBlock(i + 1, j + 30, k + 27, id);
		world.setBlock(i + 1, j + 30, k + 28, id);
		world.setBlock(i + 1, j + 30, k + 29, id);
		world.setBlock(i + 1, j + 30, k + 30, id);
		world.setBlock(i + 1, j + 30, k + 31, id);
		world.setBlock(i + 1, j + 30, k + 32, id);
		world.setBlock(i + 1, j + 30, k + 33, id);
		world.setBlock(i + 1, j + 30, k + 34, id);
		world.setBlock(i + 1, j + 30, k + 35, id);
		world.setBlock(i + 1, j + 30, k + 36, id);
		world.setBlock(i + 1, j + 30, k + 37, id);
		world.setBlock(i + 1, j + 30, k + 38, id);
		world.setBlock(i + 1, j + 30, k + 39, id);
		world.setBlock(i + 1, j + 30, k + 40, id);
		world.setBlock(i + 1, j + 30, k + 41, id);
		world.setBlock(i + 1, j + 30, k + 42, id);
		world.setBlock(i + 1, j + 30, k + 43, id);
		world.setBlock(i + 1, j + 30, k + 44, id);
		world.setBlock(i + 1, j + 30, k + 45, id);
		world.setBlock(i + 1, j + 30, k + 46, id);
		world.setBlock(i + 1, j + 30, k + 47, id);
		world.setBlock(i + 1, j + 30, k + 48, id);
		world.setBlock(i + 1, j + 30, k + 49, id);
		world.setBlock(i + 1, j + 30, k + 50, id);
		world.setBlock(i + 1, j + 30, k + 51, id);
		world.setBlock(i + 1, j + 30, k + 52, id);
		world.setBlock(i + 1, j + 30, k + 53, id);
		world.setBlock(i + 1, j + 30, k + 54, id);
		world.setBlock(i + 1, j + 30, k + 55, id);
		world.setBlock(i + 1, j + 30, k + 56, id);
		world.setBlock(i + 1, j + 30, k + 57, id);
		world.setBlock(i + 1, j + 30, k + 58, id);
		world.setBlock(i + 1, j + 30, k + 59, id);
		world.setBlock(i + 1, j + 30, k + 60, id);
		world.setBlock(i + 1, j + 30, k + 61, id);
		world.setBlock(i + 1, j + 30, k + 62, id);
		world.setBlock(i + 1, j + 30, k + 63, id);
		world.setBlock(i + 1, j + 30, k + 64, id);
		world.setBlock(i + 1, j + 30, k + 65, id);
		world.setBlock(i + 1, j + 30, k + 66, id);
		world.setBlock(i + 1, j + 30, k + 67, id);
		world.setBlock(i + 1, j + 30, k + 68, id);
		world.setBlock(i + 1, j + 30, k + 69, id);
		world.setBlock(i + 1, j + 30, k + 70, id);
		world.setBlock(i + 1, j + 30, k + 71, id);
		world.setBlock(i + 1, j + 30, k + 72, id);
		world.setBlock(i + 1, j + 30, k + 73, id);
		world.setBlock(i + 1, j + 30, k + 74, id);
		world.setBlock(i + 1, j + 30, k + 75, id);
		world.setBlock(i + 1, j + 30, k + 76, id);
		world.setBlock(i + 1, j + 30, k + 77, id);
		world.setBlock(i + 1, j + 30, k + 78, id);
		world.setBlock(i + 1, j + 30, k + 79, id);
		world.setBlock(i + 1, j + 31, k + 0, id);
		world.setBlock(i + 1, j + 31, k + 79, id);
		world.setBlock(i + 1, j + 32, k + 0, id);
		world.setBlock(i + 1, j + 32, k + 79, id);
		world.setBlock(i + 1, j + 33, k + 0, id);
		world.setBlock(i + 1, j + 33, k + 79, id);
		world.setBlock(i + 1, j + 34, k + 0, id);
		world.setBlock(i + 1, j + 34, k + 79, id);
		world.setBlock(i + 1, j + 35, k + 0, id);
		world.setBlock(i + 1, j + 35, k + 79, id);
		world.setBlock(i + 1, j + 36, k + 0, id);
		world.setBlock(i + 1, j + 36, k + 1, id);
		world.setBlock(i + 1, j + 36, k + 2, id);
		world.setBlock(i + 1, j + 36, k + 3, id);
		world.setBlock(i + 1, j + 36, k + 4, id);
		world.setBlock(i + 1, j + 36, k + 5, id);
		world.setBlock(i + 1, j + 36, k + 6, id);
		world.setBlock(i + 1, j + 36, k + 7, id);
		world.setBlock(i + 1, j + 36, k + 8, id);
		world.setBlock(i + 1, j + 36, k + 9, id);
		world.setBlock(i + 1, j + 36, k + 10, id);
		world.setBlock(i + 1, j + 36, k + 11, id);
		world.setBlock(i + 1, j + 36, k + 12, id);
		world.setBlock(i + 1, j + 36, k + 13, id);
		world.setBlock(i + 1, j + 36, k + 14, id);
		world.setBlock(i + 1, j + 36, k + 15, id);
		world.setBlock(i + 1, j + 36, k + 16, id);
		world.setBlock(i + 1, j + 36, k + 17, id);
		world.setBlock(i + 1, j + 36, k + 18, id);
		world.setBlock(i + 1, j + 36, k + 19, id);
		world.setBlock(i + 1, j + 36, k + 20, id);
		world.setBlock(i + 1, j + 36, k + 21, id);
		world.setBlock(i + 1, j + 36, k + 22, id);
		world.setBlock(i + 1, j + 36, k + 23, id);
		world.setBlock(i + 1, j + 36, k + 24, id);
		world.setBlock(i + 1, j + 36, k + 25, id);
		world.setBlock(i + 1, j + 36, k + 26, id);
		world.setBlock(i + 1, j + 36, k + 27, id);
		world.setBlock(i + 1, j + 36, k + 28, id);
		world.setBlock(i + 1, j + 36, k + 29, id);
		world.setBlock(i + 1, j + 36, k + 30, id);
		world.setBlock(i + 1, j + 36, k + 31, id);
		world.setBlock(i + 1, j + 36, k + 32, id);
		world.setBlock(i + 1, j + 36, k + 33, id);
		world.setBlock(i + 1, j + 36, k + 34, id);
		world.setBlock(i + 1, j + 36, k + 35, id);
		world.setBlock(i + 1, j + 36, k + 36, id);
		world.setBlock(i + 1, j + 36, k + 37, id);
		world.setBlock(i + 1, j + 36, k + 38, id);
		world.setBlock(i + 1, j + 36, k + 39, id);
		world.setBlock(i + 1, j + 36, k + 40, id);
		world.setBlock(i + 1, j + 36, k + 41, id);
		world.setBlock(i + 1, j + 36, k + 42, id);
		world.setBlock(i + 1, j + 36, k + 43, id);
		world.setBlock(i + 1, j + 36, k + 44, id);
		world.setBlock(i + 1, j + 36, k + 45, id);
		world.setBlock(i + 1, j + 36, k + 46, id);
		world.setBlock(i + 1, j + 36, k + 47, id);
		world.setBlock(i + 1, j + 36, k + 48, id);
		world.setBlock(i + 1, j + 36, k + 49, id);
		world.setBlock(i + 1, j + 36, k + 50, id);
		world.setBlock(i + 1, j + 36, k + 51, id);
		world.setBlock(i + 1, j + 36, k + 52, id);
		world.setBlock(i + 1, j + 36, k + 53, id);
		world.setBlock(i + 1, j + 36, k + 54, id);
		world.setBlock(i + 1, j + 36, k + 55, id);
		world.setBlock(i + 1, j + 36, k + 56, id);
		world.setBlock(i + 1, j + 36, k + 57, id);
		world.setBlock(i + 1, j + 36, k + 58, id);
		world.setBlock(i + 1, j + 36, k + 59, id);
		world.setBlock(i + 1, j + 36, k + 60, id);
		world.setBlock(i + 1, j + 36, k + 61, id);
		world.setBlock(i + 1, j + 36, k + 62, id);
		world.setBlock(i + 1, j + 36, k + 63, id);
		world.setBlock(i + 1, j + 36, k + 64, id);
		world.setBlock(i + 1, j + 36, k + 65, id);
		world.setBlock(i + 1, j + 36, k + 66, id);
		world.setBlock(i + 1, j + 36, k + 67, id);
		world.setBlock(i + 1, j + 36, k + 68, id);
		world.setBlock(i + 1, j + 36, k + 69, id);
		world.setBlock(i + 1, j + 36, k + 70, id);
		world.setBlock(i + 1, j + 36, k + 71, id);
		world.setBlock(i + 1, j + 36, k + 72, id);
		world.setBlock(i + 1, j + 36, k + 73, id);
		world.setBlock(i + 1, j + 36, k + 74, id);
		world.setBlock(i + 1, j + 36, k + 75, id);
		world.setBlock(i + 1, j + 36, k + 76, id);
		world.setBlock(i + 1, j + 36, k + 77, id);
		world.setBlock(i + 1, j + 36, k + 78, id);
		world.setBlock(i + 1, j + 36, k + 79, id);
		world.setBlock(i + 2, j + 19, k + 0, id);
		world.setBlock(i + 2, j + 19, k + 1, id);
		world.setBlock(i + 2, j + 19, k + 2, id);
		world.setBlock(i + 2, j + 19, k + 3, id);
		world.setBlock(i + 2, j + 19, k + 4, id);
		world.setBlock(i + 2, j + 19, k + 5, id);
		world.setBlock(i + 2, j + 19, k + 6, id);
		world.setBlock(i + 2, j + 19, k + 7, id);
		world.setBlock(i + 2, j + 19, k + 8, id);
		world.setBlock(i + 2, j + 19, k + 9, id);
		world.setBlock(i + 2, j + 19, k + 10, id);
		world.setBlock(i + 2, j + 19, k + 11, id);
		world.setBlock(i + 2, j + 19, k + 12, id);
		world.setBlock(i + 2, j + 19, k + 13, id);
		world.setBlock(i + 2, j + 19, k + 14, id);
		world.setBlock(i + 2, j + 19, k + 15, id);
		world.setBlock(i + 2, j + 19, k + 16, id);
		world.setBlock(i + 2, j + 19, k + 17, id);
		world.setBlock(i + 2, j + 19, k + 18, id);
		world.setBlock(i + 2, j + 19, k + 19, id);
		world.setBlock(i + 2, j + 19, k + 20, id);
		world.setBlock(i + 2, j + 19, k + 21, id);
		world.setBlock(i + 2, j + 19, k + 22, id);
		world.setBlock(i + 2, j + 19, k + 23, id);
		world.setBlock(i + 2, j + 19, k + 24, id);
		world.setBlock(i + 2, j + 19, k + 25, id);
		world.setBlock(i + 2, j + 19, k + 26, id);
		world.setBlock(i + 2, j + 19, k + 27, id);
		world.setBlock(i + 2, j + 19, k + 28, id);
		world.setBlock(i + 2, j + 19, k + 29, id);
		world.setBlock(i + 2, j + 19, k + 30, id);
		world.setBlock(i + 2, j + 19, k + 31, id);
		world.setBlock(i + 2, j + 19, k + 32, id);
		world.setBlock(i + 2, j + 19, k + 33, id);
		world.setBlock(i + 2, j + 19, k + 34, id);
		world.setBlock(i + 2, j + 19, k + 35, id);
		world.setBlock(i + 2, j + 19, k + 36, id);
		world.setBlock(i + 2, j + 19, k + 37, id);
		world.setBlock(i + 2, j + 19, k + 38, id);
		world.setBlock(i + 2, j + 19, k + 39, id);

		generate2(world, rand, i, j, k);
		return true;
	}

	public boolean generate2(World world, Random rand, int i, int j, int k) {
		world.setBlock(i + 2, j + 19, k + 40, id);
		world.setBlock(i + 2, j + 19, k + 41, id);
		world.setBlock(i + 2, j + 19, k + 42, id);
		world.setBlock(i + 2, j + 19, k + 43, id);
		world.setBlock(i + 2, j + 19, k + 44, id);
		world.setBlock(i + 2, j + 19, k + 45, id);
		world.setBlock(i + 2, j + 19, k + 46, id);
		world.setBlock(i + 2, j + 19, k + 47, id);
		world.setBlock(i + 2, j + 19, k + 48, id);
		world.setBlock(i + 2, j + 19, k + 49, id);
		world.setBlock(i + 2, j + 19, k + 50, id);
		world.setBlock(i + 2, j + 19, k + 51, id);
		world.setBlock(i + 2, j + 19, k + 52, id);
		world.setBlock(i + 2, j + 19, k + 53, id);
		world.setBlock(i + 2, j + 19, k + 54, id);
		world.setBlock(i + 2, j + 19, k + 55, id);
		world.setBlock(i + 2, j + 19, k + 56, id);
		world.setBlock(i + 2, j + 19, k + 57, id);
		world.setBlock(i + 2, j + 19, k + 58, id);
		world.setBlock(i + 2, j + 19, k + 59, id);
		world.setBlock(i + 2, j + 19, k + 60, id);
		world.setBlock(i + 2, j + 19, k + 61, id);
		world.setBlock(i + 2, j + 19, k + 62, id);
		world.setBlock(i + 2, j + 19, k + 63, id);
		world.setBlock(i + 2, j + 19, k + 64, id);
		world.setBlock(i + 2, j + 19, k + 65, id);
		world.setBlock(i + 2, j + 19, k + 66, id);
		world.setBlock(i + 2, j + 19, k + 67, id);
		world.setBlock(i + 2, j + 19, k + 68, id);
		world.setBlock(i + 2, j + 19, k + 69, id);
		world.setBlock(i + 2, j + 19, k + 70, id);
		world.setBlock(i + 2, j + 19, k + 71, id);
		world.setBlock(i + 2, j + 19, k + 72, id);
		world.setBlock(i + 2, j + 19, k + 73, id);
		world.setBlock(i + 2, j + 19, k + 74, id);
		world.setBlock(i + 2, j + 19, k + 75, id);
		world.setBlock(i + 2, j + 19, k + 76, id);
		world.setBlock(i + 2, j + 19, k + 77, id);
		world.setBlock(i + 2, j + 19, k + 78, id);
		world.setBlock(i + 2, j + 19, k + 79, id);
		world.setBlock(i + 2, j + 20, k + 0, id);
		world.setBlock(i + 2, j + 20, k + 79, id);
		world.setBlock(i + 2, j + 21, k + 0, id);
		world.setBlock(i + 2, j + 21, k + 79, id);
		world.setBlock(i + 2, j + 22, k + 0, id);
		world.setBlock(i + 2, j + 22, k + 79, id);
		world.setBlock(i + 2, j + 23, k + 0, id);
		world.setBlock(i + 2, j + 23, k + 79, id);
		world.setBlock(i + 2, j + 24, k + 0, id);
		world.setBlock(i + 2, j + 24, k + 79, id);
		world.setBlock(i + 2, j + 25, k + 0, id);
		world.setBlock(i + 2, j + 25, k + 1, id);
		world.setBlock(i + 2, j + 25, k + 2, id);
		world.setBlock(i + 2, j + 25, k + 3, id);
		world.setBlock(i + 2, j + 25, k + 4, id);
		world.setBlock(i + 2, j + 25, k + 5, id);
		world.setBlock(i + 2, j + 25, k + 6, id);
		world.setBlock(i + 2, j + 25, k + 7, id);
		world.setBlock(i + 2, j + 25, k + 8, id);
		world.setBlock(i + 2, j + 25, k + 9, id);
		world.setBlock(i + 2, j + 25, k + 10, id);
		world.setBlock(i + 2, j + 25, k + 11, id);
		world.setBlock(i + 2, j + 25, k + 12, id);
		world.setBlock(i + 2, j + 25, k + 13, id);
		world.setBlock(i + 2, j + 25, k + 14, id);
		world.setBlock(i + 2, j + 25, k + 15, id);
		world.setBlock(i + 2, j + 25, k + 16, id);
		world.setBlock(i + 2, j + 25, k + 17, id);
		world.setBlock(i + 2, j + 25, k + 18, id);
		world.setBlock(i + 2, j + 25, k + 19, id);
		world.setBlock(i + 2, j + 25, k + 20, id);
		world.setBlock(i + 2, j + 25, k + 21, id);
		world.setBlock(i + 2, j + 25, k + 22, id);
		world.setBlock(i + 2, j + 25, k + 23, id);
		world.setBlock(i + 2, j + 25, k + 24, id);
		world.setBlock(i + 2, j + 25, k + 25, id);
		world.setBlock(i + 2, j + 25, k + 26, id);
		world.setBlock(i + 2, j + 25, k + 27, id);
		world.setBlock(i + 2, j + 25, k + 28, id);
		world.setBlock(i + 2, j + 25, k + 29, id);
		world.setBlock(i + 2, j + 25, k + 30, id);
		world.setBlock(i + 2, j + 25, k + 31, id);
		world.setBlock(i + 2, j + 25, k + 32, id);
		world.setBlock(i + 2, j + 25, k + 33, id);
		world.setBlock(i + 2, j + 25, k + 34, id);
		world.setBlock(i + 2, j + 25, k + 35, id);
		world.setBlock(i + 2, j + 25, k + 36, id);
		world.setBlock(i + 2, j + 25, k + 37, id);
		world.setBlock(i + 2, j + 25, k + 38, id);
		world.setBlock(i + 2, j + 25, k + 39, id);
		world.setBlock(i + 2, j + 25, k + 40, id);
		world.setBlock(i + 2, j + 25, k + 41, id);
		world.setBlock(i + 2, j + 25, k + 42, id);
		world.setBlock(i + 2, j + 25, k + 43, id);
		world.setBlock(i + 2, j + 25, k + 44, id);
		world.setBlock(i + 2, j + 25, k + 45, id);
		world.setBlock(i + 2, j + 25, k + 46, id);
		world.setBlock(i + 2, j + 25, k + 47, id);
		world.setBlock(i + 2, j + 25, k + 48, id);
		world.setBlock(i + 2, j + 25, k + 49, id);
		world.setBlock(i + 2, j + 25, k + 50, id);
		world.setBlock(i + 2, j + 25, k + 51, id);
		world.setBlock(i + 2, j + 25, k + 52, id);
		world.setBlock(i + 2, j + 25, k + 53, id);
		world.setBlock(i + 2, j + 25, k + 54, id);
		world.setBlock(i + 2, j + 25, k + 55, id);
		world.setBlock(i + 2, j + 25, k + 56, id);
		world.setBlock(i + 2, j + 25, k + 57, id);
		world.setBlock(i + 2, j + 25, k + 58, id);
		world.setBlock(i + 2, j + 25, k + 59, id);
		world.setBlock(i + 2, j + 25, k + 60, id);
		world.setBlock(i + 2, j + 25, k + 61, id);
		world.setBlock(i + 2, j + 25, k + 62, id);
		world.setBlock(i + 2, j + 25, k + 63, id);
		world.setBlock(i + 2, j + 25, k + 64, id);
		world.setBlock(i + 2, j + 25, k + 65, id);
		world.setBlock(i + 2, j + 25, k + 66, id);
		world.setBlock(i + 2, j + 25, k + 67, id);
		world.setBlock(i + 2, j + 25, k + 68, id);
		world.setBlock(i + 2, j + 25, k + 69, id);
		world.setBlock(i + 2, j + 25, k + 70, id);
		world.setBlock(i + 2, j + 25, k + 71, id);
		world.setBlock(i + 2, j + 25, k + 72, id);
		world.setBlock(i + 2, j + 25, k + 73, id);
		world.setBlock(i + 2, j + 25, k + 74, id);
		world.setBlock(i + 2, j + 25, k + 75, id);
		world.setBlock(i + 2, j + 25, k + 76, id);
		world.setBlock(i + 2, j + 25, k + 77, id);
		world.setBlock(i + 2, j + 25, k + 78, id);
		world.setBlock(i + 2, j + 25, k + 79, id);
		world.setBlock(i + 2, j + 26, k + 2, id);
		world.setBlock(i + 2, j + 26, k + 3, id);
		world.setBlock(i + 2, j + 26, k + 4, id);
		world.setBlock(i + 2, j + 26, k + 75, id);
		world.setBlock(i + 2, j + 26, k + 76, id);
		world.setBlock(i + 2, j + 26, k + 77, id);
		world.setBlock(i + 2, j + 27, k + 2, id);
		world.setBlock(i + 2, j + 27, k + 3, id);
		world.setBlock(i + 2, j + 27, k + 4, id);
		world.setBlock(i + 2, j + 27, k + 75, id);
		world.setBlock(i + 2, j + 27, k + 76, id);
		world.setBlock(i + 2, j + 27, k + 77, id);
		world.setBlock(i + 2, j + 28, k + 2, id);
		world.setBlock(i + 2, j + 28, k + 3, id);
		world.setBlock(i + 2, j + 28, k + 4, id);
		world.setBlock(i + 2, j + 28, k + 75, id);
		world.setBlock(i + 2, j + 28, k + 76, id);
		world.setBlock(i + 2, j + 28, k + 77, id);
		world.setBlock(i + 2, j + 29, k + 2, id);
		world.setBlock(i + 2, j + 29, k + 3, id);
		world.setBlock(i + 2, j + 29, k + 4, id);
		world.setBlock(i + 2, j + 29, k + 75, id);
		world.setBlock(i + 2, j + 29, k + 76, id);
		world.setBlock(i + 2, j + 29, k + 77, id);
		world.setBlock(i + 2, j + 30, k + 0, id);
		world.setBlock(i + 2, j + 30, k + 1, id);
		world.setBlock(i + 2, j + 30, k + 2, id);
		world.setBlock(i + 2, j + 30, k + 3, id);
		world.setBlock(i + 2, j + 30, k + 4, id);
		world.setBlock(i + 2, j + 30, k + 5, id);
		world.setBlock(i + 2, j + 30, k + 6, id);
		world.setBlock(i + 2, j + 30, k + 7, id);
		world.setBlock(i + 2, j + 30, k + 8, id);
		world.setBlock(i + 2, j + 30, k + 9, id);
		world.setBlock(i + 2, j + 30, k + 10, id);
		world.setBlock(i + 2, j + 30, k + 11, id);
		world.setBlock(i + 2, j + 30, k + 12, id);
		world.setBlock(i + 2, j + 30, k + 13, id);
		world.setBlock(i + 2, j + 30, k + 14, id);
		world.setBlock(i + 2, j + 30, k + 15, id);
		world.setBlock(i + 2, j + 30, k + 16, id);
		world.setBlock(i + 2, j + 30, k + 17, id);
		world.setBlock(i + 2, j + 30, k + 18, id);
		world.setBlock(i + 2, j + 30, k + 19, id);
		world.setBlock(i + 2, j + 30, k + 20, id);
		world.setBlock(i + 2, j + 30, k + 21, id);
		world.setBlock(i + 2, j + 30, k + 22, id);
		world.setBlock(i + 2, j + 30, k + 23, id);
		world.setBlock(i + 2, j + 30, k + 24, id);
		world.setBlock(i + 2, j + 30, k + 25, id);
		world.setBlock(i + 2, j + 30, k + 26, id);
		world.setBlock(i + 2, j + 30, k + 27, id);
		world.setBlock(i + 2, j + 30, k + 28, id);
		world.setBlock(i + 2, j + 30, k + 29, id);
		world.setBlock(i + 2, j + 30, k + 30, id);
		world.setBlock(i + 2, j + 30, k + 31, id);
		world.setBlock(i + 2, j + 30, k + 32, id);
		world.setBlock(i + 2, j + 30, k + 33, id);
		world.setBlock(i + 2, j + 30, k + 34, id);
		world.setBlock(i + 2, j + 30, k + 35, id);
		world.setBlock(i + 2, j + 30, k + 36, id);
		world.setBlock(i + 2, j + 30, k + 37, id);
		world.setBlock(i + 2, j + 30, k + 38, id);
		world.setBlock(i + 2, j + 30, k + 39, id);
		world.setBlock(i + 2, j + 30, k + 40, id);
		world.setBlock(i + 2, j + 30, k + 41, id);
		world.setBlock(i + 2, j + 30, k + 42, id);
		world.setBlock(i + 2, j + 30, k + 43, id);
		world.setBlock(i + 2, j + 30, k + 44, id);
		world.setBlock(i + 2, j + 30, k + 45, id);
		world.setBlock(i + 2, j + 30, k + 46, id);
		world.setBlock(i + 2, j + 30, k + 47, id);
		world.setBlock(i + 2, j + 30, k + 48, id);
		world.setBlock(i + 2, j + 30, k + 49, id);
		world.setBlock(i + 2, j + 30, k + 50, id);
		world.setBlock(i + 2, j + 30, k + 51, id);
		world.setBlock(i + 2, j + 30, k + 52, id);
		world.setBlock(i + 2, j + 30, k + 53, id);
		world.setBlock(i + 2, j + 30, k + 54, id);
		world.setBlock(i + 2, j + 30, k + 55, id);
		world.setBlock(i + 2, j + 30, k + 56, id);
		world.setBlock(i + 2, j + 30, k + 57, id);
		world.setBlock(i + 2, j + 30, k + 58, id);
		world.setBlock(i + 2, j + 30, k + 59, id);
		world.setBlock(i + 2, j + 30, k + 60, id);
		world.setBlock(i + 2, j + 30, k + 61, id);
		world.setBlock(i + 2, j + 30, k + 62, id);
		world.setBlock(i + 2, j + 30, k + 63, id);
		world.setBlock(i + 2, j + 30, k + 64, id);
		world.setBlock(i + 2, j + 30, k + 65, id);
		world.setBlock(i + 2, j + 30, k + 66, id);
		world.setBlock(i + 2, j + 30, k + 67, id);
		world.setBlock(i + 2, j + 30, k + 68, id);
		world.setBlock(i + 2, j + 30, k + 69, id);
		world.setBlock(i + 2, j + 30, k + 70, id);
		world.setBlock(i + 2, j + 30, k + 71, id);
		world.setBlock(i + 2, j + 30, k + 72, id);
		world.setBlock(i + 2, j + 30, k + 73, id);
		world.setBlock(i + 2, j + 30, k + 74, id);
		world.setBlock(i + 2, j + 30, k + 75, id);
		world.setBlock(i + 2, j + 30, k + 76, id);
		world.setBlock(i + 2, j + 30, k + 77, id);
		world.setBlock(i + 2, j + 30, k + 78, id);
		world.setBlock(i + 2, j + 30, k + 79, id);
		world.setBlock(i + 2, j + 31, k + 0, id);
		world.setBlock(i + 2, j + 31, k + 79, id);
		world.setBlock(i + 2, j + 32, k + 0, id);
		world.setBlock(i + 2, j + 32, k + 79, id);
		world.setBlock(i + 2, j + 33, k + 0, id);
		world.setBlock(i + 2, j + 33, k + 79, id);
		world.setBlock(i + 2, j + 34, k + 0, id);
		world.setBlock(i + 2, j + 34, k + 79, id);
		world.setBlock(i + 2, j + 35, k + 0, id);
		world.setBlock(i + 2, j + 35, k + 79, id);
		world.setBlock(i + 2, j + 36, k + 0, id);
		world.setBlock(i + 2, j + 36, k + 1, id);
		world.setBlock(i + 2, j + 36, k + 2, id);
		world.setBlock(i + 2, j + 36, k + 3, id);
		world.setBlock(i + 2, j + 36, k + 4, id);
		world.setBlock(i + 2, j + 36, k + 5, id);
		world.setBlock(i + 2, j + 36, k + 6, id);
		world.setBlock(i + 2, j + 36, k + 7, id);
		world.setBlock(i + 2, j + 36, k + 8, id);
		world.setBlock(i + 2, j + 36, k + 9, id);
		world.setBlock(i + 2, j + 36, k + 10, id);
		world.setBlock(i + 2, j + 36, k + 11, id);
		world.setBlock(i + 2, j + 36, k + 12, id);
		world.setBlock(i + 2, j + 36, k + 13, id);
		world.setBlock(i + 2, j + 36, k + 14, id);
		world.setBlock(i + 2, j + 36, k + 15, id);
		world.setBlock(i + 2, j + 36, k + 16, id);
		world.setBlock(i + 2, j + 36, k + 17, id);
		world.setBlock(i + 2, j + 36, k + 18, id);
		world.setBlock(i + 2, j + 36, k + 19, id);
		world.setBlock(i + 2, j + 36, k + 20, id);
		world.setBlock(i + 2, j + 36, k + 21, id);
		world.setBlock(i + 2, j + 36, k + 22, id);
		world.setBlock(i + 2, j + 36, k + 23, id);
		world.setBlock(i + 2, j + 36, k + 24, id);
		world.setBlock(i + 2, j + 36, k + 25, id);
		world.setBlock(i + 2, j + 36, k + 26, id);
		world.setBlock(i + 2, j + 36, k + 27, id);
		world.setBlock(i + 2, j + 36, k + 28, id);
		world.setBlock(i + 2, j + 36, k + 29, id);
		world.setBlock(i + 2, j + 36, k + 30, id);
		world.setBlock(i + 2, j + 36, k + 31, id);
		world.setBlock(i + 2, j + 36, k + 32, id);
		world.setBlock(i + 2, j + 36, k + 33, id);
		world.setBlock(i + 2, j + 36, k + 34, id);
		world.setBlock(i + 2, j + 36, k + 35, id);
		world.setBlock(i + 2, j + 36, k + 36, id);
		world.setBlock(i + 2, j + 36, k + 37, id);
		world.setBlock(i + 2, j + 36, k + 38, id);
		world.setBlock(i + 2, j + 36, k + 39, id);
		world.setBlock(i + 2, j + 36, k + 40, id);
		world.setBlock(i + 2, j + 36, k + 41, id);
		world.setBlock(i + 2, j + 36, k + 42, id);
		world.setBlock(i + 2, j + 36, k + 43, id);
		world.setBlock(i + 2, j + 36, k + 44, id);
		world.setBlock(i + 2, j + 36, k + 45, id);
		world.setBlock(i + 2, j + 36, k + 46, id);
		world.setBlock(i + 2, j + 36, k + 47, id);
		world.setBlock(i + 2, j + 36, k + 48, id);
		world.setBlock(i + 2, j + 36, k + 49, id);
		world.setBlock(i + 2, j + 36, k + 50, id);
		world.setBlock(i + 2, j + 36, k + 51, id);
		world.setBlock(i + 2, j + 36, k + 52, id);
		world.setBlock(i + 2, j + 36, k + 53, id);
		world.setBlock(i + 2, j + 36, k + 54, id);
		world.setBlock(i + 2, j + 36, k + 55, id);
		world.setBlock(i + 2, j + 36, k + 56, id);
		world.setBlock(i + 2, j + 36, k + 57, id);
		world.setBlock(i + 2, j + 36, k + 58, id);
		world.setBlock(i + 2, j + 36, k + 59, id);
		world.setBlock(i + 2, j + 36, k + 60, id);
		world.setBlock(i + 2, j + 36, k + 61, id);
		world.setBlock(i + 2, j + 36, k + 62, id);
		world.setBlock(i + 2, j + 36, k + 63, id);
		world.setBlock(i + 2, j + 36, k + 64, id);
		world.setBlock(i + 2, j + 36, k + 65, id);
		world.setBlock(i + 2, j + 36, k + 66, id);
		world.setBlock(i + 2, j + 36, k + 67, id);
		world.setBlock(i + 2, j + 36, k + 68, id);
		world.setBlock(i + 2, j + 36, k + 69, id);
		world.setBlock(i + 2, j + 36, k + 70, id);
		world.setBlock(i + 2, j + 36, k + 71, id);
		world.setBlock(i + 2, j + 36, k + 72, id);
		world.setBlock(i + 2, j + 36, k + 73, id);
		world.setBlock(i + 2, j + 36, k + 74, id);
		world.setBlock(i + 2, j + 36, k + 75, id);
		world.setBlock(i + 2, j + 36, k + 76, id);
		world.setBlock(i + 2, j + 36, k + 77, id);
		world.setBlock(i + 2, j + 36, k + 78, id);
		world.setBlock(i + 2, j + 36, k + 79, id);
		world.setBlock(i + 3, j + 19, k + 0, id);
		world.setBlock(i + 3, j + 19, k + 1, id);
		world.setBlock(i + 3, j + 19, k + 2, id);
		world.setBlock(i + 3, j + 19, k + 3, id);
		world.setBlock(i + 3, j + 19, k + 4, id);
		world.setBlock(i + 3, j + 19, k + 5, id);
		world.setBlock(i + 3, j + 19, k + 6, id);
		world.setBlock(i + 3, j + 19, k + 7, id);
		world.setBlock(i + 3, j + 19, k + 8, id);
		world.setBlock(i + 3, j + 19, k + 9, id);
		world.setBlock(i + 3, j + 19, k + 10, id);
		world.setBlock(i + 3, j + 19, k + 11, id);
		world.setBlock(i + 3, j + 19, k + 12, id);
		world.setBlock(i + 3, j + 19, k + 13, id);
		world.setBlock(i + 3, j + 19, k + 14, id);
		world.setBlock(i + 3, j + 19, k + 15, id);
		world.setBlock(i + 3, j + 19, k + 16, id);
		world.setBlock(i + 3, j + 19, k + 17, id);
		world.setBlock(i + 3, j + 19, k + 18, id);
		world.setBlock(i + 3, j + 19, k + 19, id);
		world.setBlock(i + 3, j + 19, k + 20, id);
		world.setBlock(i + 3, j + 19, k + 21, id);
		world.setBlock(i + 3, j + 19, k + 22, id);
		world.setBlock(i + 3, j + 19, k + 23, id);
		world.setBlock(i + 3, j + 19, k + 24, id);
		world.setBlock(i + 3, j + 19, k + 25, id);
		world.setBlock(i + 3, j + 19, k + 26, id);
		world.setBlock(i + 3, j + 19, k + 27, id);
		world.setBlock(i + 3, j + 19, k + 28, id);
		world.setBlock(i + 3, j + 19, k + 29, id);
		world.setBlock(i + 3, j + 19, k + 30, id);
		world.setBlock(i + 3, j + 19, k + 31, id);
		world.setBlock(i + 3, j + 19, k + 32, id);
		world.setBlock(i + 3, j + 19, k + 33, id);
		world.setBlock(i + 3, j + 19, k + 34, id);
		world.setBlock(i + 3, j + 19, k + 35, id);
		world.setBlock(i + 3, j + 19, k + 36, id);
		world.setBlock(i + 3, j + 19, k + 37, id);
		world.setBlock(i + 3, j + 19, k + 38, id);
		world.setBlock(i + 3, j + 19, k + 39, id);
		world.setBlock(i + 3, j + 19, k + 40, id);
		world.setBlock(i + 3, j + 19, k + 41, id);
		world.setBlock(i + 3, j + 19, k + 42, id);
		world.setBlock(i + 3, j + 19, k + 43, id);
		world.setBlock(i + 3, j + 19, k + 44, id);
		world.setBlock(i + 3, j + 19, k + 45, id);
		world.setBlock(i + 3, j + 19, k + 46, id);
		world.setBlock(i + 3, j + 19, k + 47, id);
		world.setBlock(i + 3, j + 19, k + 48, id);
		world.setBlock(i + 3, j + 19, k + 49, id);
		world.setBlock(i + 3, j + 19, k + 50, id);
		world.setBlock(i + 3, j + 19, k + 51, id);
		world.setBlock(i + 3, j + 19, k + 52, id);
		world.setBlock(i + 3, j + 19, k + 53, id);
		world.setBlock(i + 3, j + 19, k + 54, id);
		world.setBlock(i + 3, j + 19, k + 55, id);
		world.setBlock(i + 3, j + 19, k + 56, id);
		world.setBlock(i + 3, j + 19, k + 57, id);
		world.setBlock(i + 3, j + 19, k + 58, id);
		world.setBlock(i + 3, j + 19, k + 59, id);
		world.setBlock(i + 3, j + 19, k + 60, id);
		world.setBlock(i + 3, j + 19, k + 61, id);
		world.setBlock(i + 3, j + 19, k + 62, id);
		world.setBlock(i + 3, j + 19, k + 63, id);
		world.setBlock(i + 3, j + 19, k + 64, id);
		world.setBlock(i + 3, j + 19, k + 65, id);
		world.setBlock(i + 3, j + 19, k + 66, id);
		world.setBlock(i + 3, j + 19, k + 67, id);
		world.setBlock(i + 3, j + 19, k + 68, id);
		world.setBlock(i + 3, j + 19, k + 69, id);
		world.setBlock(i + 3, j + 19, k + 70, id);
		world.setBlock(i + 3, j + 19, k + 71, id);
		world.setBlock(i + 3, j + 19, k + 72, id);
		world.setBlock(i + 3, j + 19, k + 73, id);
		world.setBlock(i + 3, j + 19, k + 74, id);
		world.setBlock(i + 3, j + 19, k + 75, id);
		world.setBlock(i + 3, j + 19, k + 76, id);
		world.setBlock(i + 3, j + 19, k + 77, id);
		world.setBlock(i + 3, j + 19, k + 78, id);
		world.setBlock(i + 3, j + 19, k + 79, id);
		world.setBlock(i + 3, j + 20, k + 0, id);
		world.setBlock(i + 3, j + 20, k + 79, id);
		world.setBlock(i + 3, j + 21, k + 0, id);
		world.setBlock(i + 3, j + 21, k + 79, id);
		world.setBlock(i + 3, j + 22, k + 0, id);
		world.setBlock(i + 3, j + 22, k + 79, id);
		world.setBlock(i + 3, j + 23, k + 0, id);
		world.setBlock(i + 3, j + 23, k + 79, id);
		world.setBlock(i + 3, j + 24, k + 0, id);
		world.setBlock(i + 3, j + 24, k + 79, id);
		world.setBlock(i + 3, j + 25, k + 0, id);
		world.setBlock(i + 3, j + 25, k + 1, id);
		world.setBlock(i + 3, j + 25, k + 2, id);
		world.setBlock(i + 3, j + 25, k + 4, id);
		world.setBlock(i + 3, j + 25, k + 5, id);
		world.setBlock(i + 3, j + 25, k + 6, id);
		world.setBlock(i + 3, j + 25, k + 7, id);
		world.setBlock(i + 3, j + 25, k + 8, id);
		world.setBlock(i + 3, j + 25, k + 9, id);
		world.setBlock(i + 3, j + 25, k + 10, id);
		world.setBlock(i + 3, j + 25, k + 11, id);
		world.setBlock(i + 3, j + 25, k + 12, id);
		world.setBlock(i + 3, j + 25, k + 13, id);
		world.setBlock(i + 3, j + 25, k + 14, id);
		world.setBlock(i + 3, j + 25, k + 15, id);
		world.setBlock(i + 3, j + 25, k + 16, id);
		world.setBlock(i + 3, j + 25, k + 17, id);
		world.setBlock(i + 3, j + 25, k + 18, id);
		world.setBlock(i + 3, j + 25, k + 19, id);
		world.setBlock(i + 3, j + 25, k + 20, id);
		world.setBlock(i + 3, j + 25, k + 21, id);
		world.setBlock(i + 3, j + 25, k + 22, id);
		world.setBlock(i + 3, j + 25, k + 23, id);
		world.setBlock(i + 3, j + 25, k + 24, id);
		world.setBlock(i + 3, j + 25, k + 25, id);
		world.setBlock(i + 3, j + 25, k + 26, id);
		world.setBlock(i + 3, j + 25, k + 27, id);
		world.setBlock(i + 3, j + 25, k + 28, id);
		world.setBlock(i + 3, j + 25, k + 29, id);
		world.setBlock(i + 3, j + 25, k + 30, id);
		world.setBlock(i + 3, j + 25, k + 31, id);
		world.setBlock(i + 3, j + 25, k + 32, id);
		world.setBlock(i + 3, j + 25, k + 33, id);
		world.setBlock(i + 3, j + 25, k + 34, id);
		world.setBlock(i + 3, j + 25, k + 35, id);
		world.setBlock(i + 3, j + 25, k + 36, id);
		world.setBlock(i + 3, j + 25, k + 37, id);
		world.setBlock(i + 3, j + 25, k + 38, id);
		world.setBlock(i + 3, j + 25, k + 39, id);
		world.setBlock(i + 3, j + 25, k + 40, id);
		world.setBlock(i + 3, j + 25, k + 41, id);
		world.setBlock(i + 3, j + 25, k + 42, id);
		world.setBlock(i + 3, j + 25, k + 43, id);
		world.setBlock(i + 3, j + 25, k + 44, id);
		world.setBlock(i + 3, j + 25, k + 45, id);
		world.setBlock(i + 3, j + 25, k + 46, id);
		world.setBlock(i + 3, j + 25, k + 47, id);
		world.setBlock(i + 3, j + 25, k + 48, id);
		world.setBlock(i + 3, j + 25, k + 49, id);
		world.setBlock(i + 3, j + 25, k + 50, id);
		world.setBlock(i + 3, j + 25, k + 51, id);
		world.setBlock(i + 3, j + 25, k + 52, id);
		world.setBlock(i + 3, j + 25, k + 53, id);
		world.setBlock(i + 3, j + 25, k + 54, id);
		world.setBlock(i + 3, j + 25, k + 55, id);
		world.setBlock(i + 3, j + 25, k + 56, id);
		world.setBlock(i + 3, j + 25, k + 57, id);
		world.setBlock(i + 3, j + 25, k + 58, id);
		world.setBlock(i + 3, j + 25, k + 59, id);
		world.setBlock(i + 3, j + 25, k + 60, id);
		world.setBlock(i + 3, j + 25, k + 61, id);
		world.setBlock(i + 3, j + 25, k + 62, id);
		world.setBlock(i + 3, j + 25, k + 63, id);
		world.setBlock(i + 3, j + 25, k + 64, id);
		world.setBlock(i + 3, j + 25, k + 65, id);
		world.setBlock(i + 3, j + 25, k + 66, id);
		world.setBlock(i + 3, j + 25, k + 67, id);
		world.setBlock(i + 3, j + 25, k + 68, id);
		world.setBlock(i + 3, j + 25, k + 69, id);
		world.setBlock(i + 3, j + 25, k + 70, id);
		world.setBlock(i + 3, j + 25, k + 71, id);
		world.setBlock(i + 3, j + 25, k + 72, id);
		world.setBlock(i + 3, j + 25, k + 73, id);
		world.setBlock(i + 3, j + 25, k + 74, id);
		world.setBlock(i + 3, j + 25, k + 75, id);
		world.setBlock(i + 3, j + 25, k + 77, id);
		world.setBlock(i + 3, j + 25, k + 78, id);
		world.setBlock(i + 3, j + 25, k + 79, id);
		world.setBlock(i + 3, j + 26, k + 2, id);
		world.setBlock(i + 3, j + 26, k + 4, id);
		world.setBlock(i + 3, j + 26, k + 75, id);
		world.setBlock(i + 3, j + 26, k + 77, id);
		world.setBlock(i + 3, j + 27, k + 2, id);
		world.setBlock(i + 3, j + 27, k + 4, id);
		world.setBlock(i + 3, j + 27, k + 75, id);
		world.setBlock(i + 3, j + 27, k + 77, id);
		world.setBlock(i + 3, j + 28, k + 2, id);
		world.setBlock(i + 3, j + 28, k + 4, id);
		world.setBlock(i + 3, j + 28, k + 75, id);
		world.setBlock(i + 3, j + 28, k + 77, id);
		world.setBlock(i + 3, j + 29, k + 2, id);
		world.setBlock(i + 3, j + 29, k + 4, id);
		world.setBlock(i + 3, j + 29, k + 75, id);
		world.setBlock(i + 3, j + 29, k + 77, id);
		world.setBlock(i + 3, j + 30, k + 0, id);
		world.setBlock(i + 3, j + 30, k + 1, id);
		world.setBlock(i + 3, j + 30, k + 2, id);
		world.setBlock(i + 3, j + 30, k + 4, id);
		world.setBlock(i + 3, j + 30, k + 5, id);
		world.setBlock(i + 3, j + 30, k + 6, id);
		world.setBlock(i + 3, j + 30, k + 7, id);
		world.setBlock(i + 3, j + 30, k + 8, id);
		world.setBlock(i + 3, j + 30, k + 9, id);
		world.setBlock(i + 3, j + 30, k + 10, id);
		world.setBlock(i + 3, j + 30, k + 11, id);
		world.setBlock(i + 3, j + 30, k + 12, id);
		world.setBlock(i + 3, j + 30, k + 13, id);
		world.setBlock(i + 3, j + 30, k + 14, id);
		world.setBlock(i + 3, j + 30, k + 15, id);
		world.setBlock(i + 3, j + 30, k + 16, id);
		world.setBlock(i + 3, j + 30, k + 17, id);
		world.setBlock(i + 3, j + 30, k + 18, id);
		world.setBlock(i + 3, j + 30, k + 19, id);
		world.setBlock(i + 3, j + 30, k + 20, id);
		world.setBlock(i + 3, j + 30, k + 21, id);
		world.setBlock(i + 3, j + 30, k + 22, id);
		world.setBlock(i + 3, j + 30, k + 23, id);
		world.setBlock(i + 3, j + 30, k + 24, id);
		world.setBlock(i + 3, j + 30, k + 25, id);
		world.setBlock(i + 3, j + 30, k + 26, id);
		world.setBlock(i + 3, j + 30, k + 27, id);
		world.setBlock(i + 3, j + 30, k + 28, id);
		world.setBlock(i + 3, j + 30, k + 29, id);
		world.setBlock(i + 3, j + 30, k + 30, id);
		world.setBlock(i + 3, j + 30, k + 31, id);
		world.setBlock(i + 3, j + 30, k + 32, id);
		world.setBlock(i + 3, j + 30, k + 33, id);
		world.setBlock(i + 3, j + 30, k + 34, id);
		world.setBlock(i + 3, j + 30, k + 35, id);
		world.setBlock(i + 3, j + 30, k + 36, id);
		world.setBlock(i + 3, j + 30, k + 37, id);
		world.setBlock(i + 3, j + 30, k + 38, id);
		world.setBlock(i + 3, j + 30, k + 39, id);
		world.setBlock(i + 3, j + 30, k + 40, id);
		world.setBlock(i + 3, j + 30, k + 41, id);
		world.setBlock(i + 3, j + 30, k + 42, id);
		world.setBlock(i + 3, j + 30, k + 43, id);
		world.setBlock(i + 3, j + 30, k + 44, id);
		world.setBlock(i + 3, j + 30, k + 45, id);
		world.setBlock(i + 3, j + 30, k + 46, id);
		world.setBlock(i + 3, j + 30, k + 47, id);
		world.setBlock(i + 3, j + 30, k + 48, id);
		world.setBlock(i + 3, j + 30, k + 49, id);
		world.setBlock(i + 3, j + 30, k + 50, id);
		world.setBlock(i + 3, j + 30, k + 51, id);
		world.setBlock(i + 3, j + 30, k + 52, id);
		world.setBlock(i + 3, j + 30, k + 53, id);
		world.setBlock(i + 3, j + 30, k + 54, id);
		world.setBlock(i + 3, j + 30, k + 55, id);
		world.setBlock(i + 3, j + 30, k + 56, id);
		world.setBlock(i + 3, j + 30, k + 57, id);
		world.setBlock(i + 3, j + 30, k + 58, id);
		world.setBlock(i + 3, j + 30, k + 59, id);
		world.setBlock(i + 3, j + 30, k + 60, id);
		world.setBlock(i + 3, j + 30, k + 61, id);
		world.setBlock(i + 3, j + 30, k + 62, id);
		world.setBlock(i + 3, j + 30, k + 63, id);
		world.setBlock(i + 3, j + 30, k + 64, id);
		world.setBlock(i + 3, j + 30, k + 65, id);
		world.setBlock(i + 3, j + 30, k + 66, id);
		world.setBlock(i + 3, j + 30, k + 67, id);
		world.setBlock(i + 3, j + 30, k + 68, id);
		world.setBlock(i + 3, j + 30, k + 69, id);
		world.setBlock(i + 3, j + 30, k + 70, id);
		world.setBlock(i + 3, j + 30, k + 71, id);
		world.setBlock(i + 3, j + 30, k + 72, id);
		world.setBlock(i + 3, j + 30, k + 73, id);
		world.setBlock(i + 3, j + 30, k + 74, id);
		world.setBlock(i + 3, j + 30, k + 75, id);
		world.setBlock(i + 3, j + 30, k + 77, id);
		world.setBlock(i + 3, j + 30, k + 78, id);
		world.setBlock(i + 3, j + 30, k + 79, id);
		world.setBlock(i + 3, j + 31, k + 0, id);
		world.setBlock(i + 3, j + 31, k + 79, id);
		world.setBlock(i + 3, j + 32, k + 0, id);
		world.setBlock(i + 3, j + 32, k + 79, id);
		world.setBlock(i + 3, j + 33, k + 0, id);
		world.setBlock(i + 3, j + 33, k + 79, id);
		world.setBlock(i + 3, j + 34, k + 0, id);
		world.setBlock(i + 3, j + 34, k + 79, id);
		world.setBlock(i + 3, j + 35, k + 0, id);
		world.setBlock(i + 3, j + 35, k + 79, id);
		world.setBlock(i + 3, j + 36, k + 0, id);
		world.setBlock(i + 3, j + 36, k + 1, id);
		world.setBlock(i + 3, j + 36, k + 2, id);
		world.setBlock(i + 3, j + 36, k + 3, id);
		world.setBlock(i + 3, j + 36, k + 4, id);
		world.setBlock(i + 3, j + 36, k + 5, id);
		world.setBlock(i + 3, j + 36, k + 6, id);
		world.setBlock(i + 3, j + 36, k + 7, id);
		world.setBlock(i + 3, j + 36, k + 8, id);
		world.setBlock(i + 3, j + 36, k + 9, id);
		world.setBlock(i + 3, j + 36, k + 10, id);
		world.setBlock(i + 3, j + 36, k + 11, id);
		world.setBlock(i + 3, j + 36, k + 12, id);
		world.setBlock(i + 3, j + 36, k + 13, id);
		world.setBlock(i + 3, j + 36, k + 14, id);
		world.setBlock(i + 3, j + 36, k + 15, id);
		world.setBlock(i + 3, j + 36, k + 16, id);
		world.setBlock(i + 3, j + 36, k + 17, id);
		world.setBlock(i + 3, j + 36, k + 18, id);
		world.setBlock(i + 3, j + 36, k + 19, id);
		world.setBlock(i + 3, j + 36, k + 20, id);
		world.setBlock(i + 3, j + 36, k + 21, id);
		world.setBlock(i + 3, j + 36, k + 22, id);
		world.setBlock(i + 3, j + 36, k + 23, id);
		world.setBlock(i + 3, j + 36, k + 24, id);
		world.setBlock(i + 3, j + 36, k + 25, id);
		world.setBlock(i + 3, j + 36, k + 26, id);
		world.setBlock(i + 3, j + 36, k + 27, id);
		world.setBlock(i + 3, j + 36, k + 28, id);
		world.setBlock(i + 3, j + 36, k + 29, id);
		world.setBlock(i + 3, j + 36, k + 30, id);
		world.setBlock(i + 3, j + 36, k + 31, id);
		world.setBlock(i + 3, j + 36, k + 32, id);
		world.setBlock(i + 3, j + 36, k + 33, id);
		world.setBlock(i + 3, j + 36, k + 34, id);
		world.setBlock(i + 3, j + 36, k + 35, id);
		world.setBlock(i + 3, j + 36, k + 36, id);
		world.setBlock(i + 3, j + 36, k + 37, id);
		world.setBlock(i + 3, j + 36, k + 38, id);
		world.setBlock(i + 3, j + 36, k + 39, id);
		world.setBlock(i + 3, j + 36, k + 40, id);
		world.setBlock(i + 3, j + 36, k + 41, id);
		world.setBlock(i + 3, j + 36, k + 42, id);
		world.setBlock(i + 3, j + 36, k + 43, id);
		world.setBlock(i + 3, j + 36, k + 44, id);
		world.setBlock(i + 3, j + 36, k + 45, id);
		world.setBlock(i + 3, j + 36, k + 46, id);
		world.setBlock(i + 3, j + 36, k + 47, id);
		world.setBlock(i + 3, j + 36, k + 48, id);
		world.setBlock(i + 3, j + 36, k + 49, id);
		world.setBlock(i + 3, j + 36, k + 50, id);
		world.setBlock(i + 3, j + 36, k + 51, id);
		world.setBlock(i + 3, j + 36, k + 52, id);
		world.setBlock(i + 3, j + 36, k + 53, id);
		world.setBlock(i + 3, j + 36, k + 54, id);
		world.setBlock(i + 3, j + 36, k + 55, id);
		world.setBlock(i + 3, j + 36, k + 56, id);
		world.setBlock(i + 3, j + 36, k + 57, id);
		world.setBlock(i + 3, j + 36, k + 58, id);
		world.setBlock(i + 3, j + 36, k + 59, id);
		world.setBlock(i + 3, j + 36, k + 60, id);
		world.setBlock(i + 3, j + 36, k + 61, id);
		world.setBlock(i + 3, j + 36, k + 62, id);
		world.setBlock(i + 3, j + 36, k + 63, id);
		world.setBlock(i + 3, j + 36, k + 64, id);
		world.setBlock(i + 3, j + 36, k + 65, id);
		world.setBlock(i + 3, j + 36, k + 66, id);
		world.setBlock(i + 3, j + 36, k + 67, id);
		world.setBlock(i + 3, j + 36, k + 68, id);
		world.setBlock(i + 3, j + 36, k + 69, id);
		world.setBlock(i + 3, j + 36, k + 70, id);
		world.setBlock(i + 3, j + 36, k + 71, id);
		world.setBlock(i + 3, j + 36, k + 72, id);
		world.setBlock(i + 3, j + 36, k + 73, id);
		world.setBlock(i + 3, j + 36, k + 74, id);
		world.setBlock(i + 3, j + 36, k + 75, id);
		world.setBlock(i + 3, j + 36, k + 76, id);
		world.setBlock(i + 3, j + 36, k + 77, id);
		world.setBlock(i + 3, j + 36, k + 78, id);
		world.setBlock(i + 3, j + 36, k + 79, id);
		world.setBlock(i + 4, j + 19, k + 0, id);
		world.setBlock(i + 4, j + 19, k + 1, id);
		world.setBlock(i + 4, j + 19, k + 2, id);
		world.setBlock(i + 4, j + 19, k + 3, id);
		world.setBlock(i + 4, j + 19, k + 4, id);
		world.setBlock(i + 4, j + 19, k + 5, id);
		world.setBlock(i + 4, j + 19, k + 6, id);
		world.setBlock(i + 4, j + 19, k + 7, id);
		world.setBlock(i + 4, j + 19, k + 8, id);
		world.setBlock(i + 4, j + 19, k + 9, id);
		world.setBlock(i + 4, j + 19, k + 10, id);
		world.setBlock(i + 4, j + 19, k + 11, id);
		world.setBlock(i + 4, j + 19, k + 12, id);
		world.setBlock(i + 4, j + 19, k + 13, id);
		world.setBlock(i + 4, j + 19, k + 14, id);
		world.setBlock(i + 4, j + 19, k + 15, id);
		world.setBlock(i + 4, j + 19, k + 16, id);
		world.setBlock(i + 4, j + 19, k + 17, id);
		world.setBlock(i + 4, j + 19, k + 18, id);
		world.setBlock(i + 4, j + 19, k + 19, id);
		world.setBlock(i + 4, j + 19, k + 20, id);
		world.setBlock(i + 4, j + 19, k + 21, id);
		world.setBlock(i + 4, j + 19, k + 22, id);
		world.setBlock(i + 4, j + 19, k + 23, id);
		world.setBlock(i + 4, j + 19, k + 24, id);
		world.setBlock(i + 4, j + 19, k + 25, id);
		world.setBlock(i + 4, j + 19, k + 26, id);
		world.setBlock(i + 4, j + 19, k + 27, id);
		world.setBlock(i + 4, j + 19, k + 28, id);
		world.setBlock(i + 4, j + 19, k + 29, id);
		world.setBlock(i + 4, j + 19, k + 30, id);
		world.setBlock(i + 4, j + 19, k + 31, id);
		world.setBlock(i + 4, j + 19, k + 32, id);
		world.setBlock(i + 4, j + 19, k + 33, id);
		world.setBlock(i + 4, j + 19, k + 34, id);
		world.setBlock(i + 4, j + 19, k + 35, id);
		world.setBlock(i + 4, j + 19, k + 36, id);
		world.setBlock(i + 4, j + 19, k + 37, id);
		world.setBlock(i + 4, j + 19, k + 38, id);
		world.setBlock(i + 4, j + 19, k + 39, id);
